Workbook

Sheet TỔNG HỢP
A3: BÁO CÁO TỔNG HỢP KẾT QUẢ THỰC HIỆN CÔNG TÁC BẢO DƯỠNG SỬA CHỮA TẠI CHI NHÁNH MIỀN BẮC
A4: NĂM 20xy
A5: (Ban hành kèm theo Quyết định số …….…/QĐ-CNMB ngày …….…tháng …...… năm 20xy của Giám đốc Chi nhánh)
A6: TT | B6: NỘI DUNG CÔNG VIỆC | C6: Số lượng | D6: Chi phí KH 20xy | E6: Tháng 01/20xy | K6: Tháng 02/20xy | Q6: Tháng 03/20xy | W6: Tháng 04/20xy | AC6: Tháng 05/20xy | AI6: Tháng 06/20xy | AO6: Tháng 07/20xy | AU6: Tháng 08/20xy | BA6: Tháng 09/20xy | BG6: Tháng 10/20xy | BM6: Tháng 11/20xy | BS6: Tháng 12/20xy | BY6: Lũy kế từ 01/01 đến tháng báo cáo | CA6: So sánh % LKTH so với KH | CC6: Ghi chú
E7: Kế hoạch | G7: Thực hiện | I7: % | K7: Kế hoạch | M7: Thực hiện | O7: % | Q7: Kế hoạch | S7: Thực hiện | U7: % | W7: Kế hoạch | Y7: Thực hiện | AA7: % | AC7: Kế hoạch | AE7: Thực hiện | AG7: % | AI7: Kế hoạch | AK7: Thực hiện | AM7: % | AO7: Kế hoạch | AQ7: Thực hiện | AS7: % | AU7: Kế hoạch | AW7: Thực hiện | AY7: % | BA7: Kế hoạch | BC7: Thực hiện | BE7: % | BG7: Kế hoạch | BI7: Thực hiện | BK7: % | BM7: Kế hoạch | BO7: Thực hiện | BQ7: % | BS7: Kế hoạch | BU7: Thực hiện | BW7: %
E8: SL | F8: Giá trị (VNĐ) | G8: SL | H8: Giá trị (VNĐ) | I8: SL | J8: Giá trị | K8: SL | L8: Giá trị (VNĐ) | M8: SL | N8: Giá trị (VNĐ) | O8: SL | P8: Giá trị | Q8: SL | R8: Giá trị (VNĐ) | S8: SL | T8: Giá trị (VNĐ) | U8: SL | V8: Giá trị | W8: SL | X8: Giá trị (VNĐ) | Y8: SL | Z8: Giá trị (VNĐ) | AA8: SL | AB8: Giá trị | AC8: SL | AD8: Giá trị (VNĐ) | AE8: SL | AF8: Giá trị (VNĐ) | AG8: SL | AH8: Giá trị | AI8: SL | AJ8: Giá trị (VNĐ) | AK8: SL | AL8: Giá trị (VNĐ) | AM8: SL | AN8: Giá trị | AO8: SL | AP8: Giá trị (VNĐ) | AQ8: SL | AR8: Giá trị (VNĐ) | AS8: SL | AT8: Giá trị | AU8: SL | AV8: Giá trị (VNĐ) | AW8: SL | AX8: Giá trị (VNĐ) | AY8: SL | AZ8: Giá trị | BA8: SL | BB8: Giá trị (VNĐ) | BC8: SL | BD8: Giá trị (VNĐ) | BE8: SL | BF8: Giá trị | BG8: SL | BH8: Giá trị (VNĐ) | BI8: SL | BJ8: Giá trị (VNĐ) | BK8: SL | BL8: Giá trị | BM8: SL | BN8: Giá trị (VNĐ) | BO8: SL | BP8: Giá trị (VNĐ) | BQ8: SL | BR8: Giá trị | BS8: SL | BT8: Giá trị (VNĐ) | BU8: SL | BV8: Giá trị (VNĐ) | BW8: SL | BX8: Giá trị | BY8: SL | BZ8: Giá trị (VNĐ) | CA8: %SL | CB8: %Giá trị
B9: CỘNG | C9: =SUM(C10:C15) -> 0 | D9: =SUM(D10:D15) -> 0 | G9: =SUM(G10:G15) -> 0 | H9: =SUM(H10:H15) -> 0 | M9: =SUM(M10:M15) -> 0 | N9: =SUM(N10:N15) -> 0 | S9: =SUM(S10:S15) -> 0 | T9: =SUM(T10:T15) -> 0 | W9: =SUM(W10:W15) -> 0 | X9: =SUM(X10:X15) -> 0 | Y9: =SUM(Y10:Y15) -> 0 | Z9: =SUM(Z10:Z15) -> 0 | AE9: =SUM(AE10:AE15) -> 0 | AF9: =SUM(AF10:AF15) -> 0 | AK9: =SUM(AK10:AK15) -> 0 | AL9: =SUM(AL10:AL15) -> 0 | AQ9: =SUM(AQ10:AQ15) -> 0 | AR9: =SUM(AR10:AR15) -> 0 | AW9: =SUM(AW10:AW15) -> 0 | AX9: =SUM(AX10:AX15) -> 0 | BI9: =SUM(BI10:BI15) -> 0 | BJ9: =SUM(BJ10:BJ15) -> 0 | BO9: =SUM(BO10:BO15) -> 0 | BP9: =SUM(BP10:BP15) -> 0 | BV9: =SUM(BV10:BV15) -> 0 | BY9: =SUM(BY10:BY15) -> 0 | BZ9: =SUM(BZ10:BZ15) -> 0 | CA9: =BY9/C9 -> #DIV/0! | CB9: =BZ9/D9 -> #DIV/0!
A10: 1 | B10: TRẠM NẠP LPG HÀ NỘI | C10: =HN!I2 -> 0 | D10: =HN!K2 -> 0 | G10: =HNTH!A1 -> 0 | H10: =HNTH!A2 -> 0 | M10: =HNTH!B1 -> 0 | N10: =HNTH!B2 -> 0 | S10: =HNTH!C1 -> 0 | T10: =HNTH!C2 -> 0 | Y10: =HNTH!D1 -> 0 | Z10: =HNTH!D2 -> 0 | AE10: =HNTH!E1 -> 0 | AF10: =HNTH!E2 -> 0 | AK10: =HNTH!F1 -> 0 | AL10: =HNTH!F2 -> 0 | AQ10: =HNTH!G1 -> 0 | AR10: =HNTH!G2 -> 0 | AW10: =HNTH!H1 -> 0 | AX10: =HNTH!H2 -> 0 | BC10: =HNTH!I1 -> 0 | BD10: =HNTH!I2 -> 0 | BI10: =HNTH!J1 -> 0 | BJ10: =HNTH!J2 -> 0 | BO10: =HNTH!K1 -> 0 | BP10: =HNTH!K2 -> 0 | BU10: =HNTH!L1 -> 0 | BV10: =HNTH!L2 -> 0 | BY10: =INDIRECT("'HN'!R2") -> 0 | BZ10: =INDIRECT("HN!L2") -> 0 | CA10: =BY10/C10 -> #DIV/0! | CB10: =BZ10/D10 -> #DIV/0!
A11: 2 | B11: TRẠM NẠP LPG NAM ĐỊNH | C11: =INDIRECT("'NĐ'!I2") -> 0 | D11: =INDIRECT("'NĐ'!K2") -> 0 | G11: =NĐTH!A1 -> 0 | H11: =NĐTH!A2 -> 0 | M11: =NĐTH!B1 -> 0 | N11: =NĐTH!B2 -> 0 | S11: =NĐTH!C1 -> 0 | T11: =NĐTH!C2 -> 0 | Y11: =NĐTH!D1 -> 0 | Z11: =NĐTH!D2 -> 0 | AE11: =NĐTH!E1 -> 0 | AF11: =NĐTH!E2 -> 0 | AK11: =NĐTH!F1 -> 0 | AL11: =NĐTH!F2 -> 0 | AQ11: =NĐTH!G1 -> 0 | AR11: =NĐTH!G2 -> 0 | AW11: =NĐTH!H1 -> 0 | AX11: =NĐTH!H2 -> 0 | BC11: =NĐTH!I1 -> 0 | BD11: =NĐTH!I2 -> 0 | BI11: =NĐTH!J1 -> 0 | BJ11: =NĐTH!J2 -> 0 | BO11: =NĐTH!K1 -> 0 | BP11: =NĐTH!K2 -> 0 | BU11: =NĐTH!L1 -> 0 | BV11: =NĐTH!L2 -> 0 | BY11: =INDIRECT("'NĐ'!R2") -> 0 | BZ11: =INDIRECT("NĐ!L2") -> 0 | CA11: =BY11/C11 -> #DIV/0! | CB11: =BZ11/D11 -> #DIV/0!
A12: 3 | B12: TTSSKĐ NAM ĐỊNH | C12: =INDIRECT("'TTSSKĐ'!I2") -> 0 | D12: =INDIRECT("'TTSSKĐ'!K2") -> 0 | G12: =TTSSKĐTH!A1 -> 0 | H12: =TTSSKĐTH!A2 -> 0 | M12: =TTSSKĐTH!B1 -> 0 | N12: =TTSSKĐTH!B2 -> 0 | S12: =TTSSKĐTH!C1 -> 0 | T12: =TTSSKĐTH!C2 -> 0 | Y12: =TTSSKĐTH!D1 -> 0 | Z12: =TTSSKĐTH!D2 -> 0 | AE12: =TTSSKĐTH!E1 -> 0 | AF12: =TTSSKĐTH!E2 -> 0 | AK12: =TTSSKĐTH!F1 -> 0 | AL12: =TTSSKĐTH!F2 -> 0 | AQ12: =TTSSKĐTH!G1 -> 0 | AR12: =TTSSKĐTH!G2 -> 0 | AW12: =TTSSKĐTH!H1 -> 0 | AX12: =TTSSKĐTH!H2 -> 0 | BC12: =TTSSKĐTH!I1 -> 0 | BD12: =TTSSKĐTH!I2 -> 0 | BI12: =TTSSKĐTH!J1 -> 0 | BJ12: =TTSSKĐTH!J2 -> 0 | BO12: =TTSSKĐTH!K1 -> 0 | BP12: =TTSSKĐTH!K2 -> 0 | BU12: =TTSSKĐTH!L1 -> 0 | BV12: =TTSSKĐTH!L2 -> 0 | BY12: =INDIRECT("'TTSSKĐ'!R2") -> 0 | BZ12: =INDIRECT("TTSSKĐ!L2") -> 0 | CA12: =BY12/C12 -> #DIV/0! | CB12: =BZ12/D12 -> #DIV/0!
A13: 4 | B13: BẢO DƯỠNG XE Ô TÔ | C13: =INDIRECT("'XT'!I2") -> 0 | D13: =INDIRECT("'XT'!K2") -> 0 | G13: =XTTH!A$1 -> 0 | H13: =XTTH!A$2 -> 0 | M13: =XTTH!E$1 -> 0 | N13: =XTTH!E$2 -> 0 | S13: =XTTH!I$1 -> 0 | T13: =XTTH!I$2 -> 0 | Y13: =XTTH!M$1 -> 0 | Z13: =XTTH!M$2 -> 0 | AE13: =XTTH!Q$1 -> 0 | AF13: =XTTH!Q$2 -> 0 | AK13: =XTTH!U$1 -> 0 | AL13: =XTTH!U$2 -> 0 | AQ13: =XTTH!Y$1 -> 0 | AR13: =XTTH!Y$2 -> 0 | AW13: =XTTH!AC$1 -> 0 | AX13: =XTTH!AC$2 -> 0 | BC13: =XTTH!AG$1 -> 0 | BD13: =XTTH!AG$2 -> 0 | BI13: =XTTH!AK$1 -> 0 | BJ13: =XTTH!AK$2 -> 0 | BO13: =XTTH!AO$1 -> 0 | BP13: =XTTH!AO$2 -> 0 | BU13: =XTTH!AS$1 -> 0 | BV13: =XTTH!AS$2 -> 0 | BY13: =INDIRECT("'XT'!R2") -> 0 | BZ13: =INDIRECT("XT!L2") -> 0 | CA13: =BY13/C13 -> #DIV/0! | CB13: =BZ13/D13 -> #DIV/0!
A14: 5 | B14: KHO LPG HẢI PHÒNG | C14: =INDIRECT("'KHP'!I2") -> 0 | D14: =INDIRECT("'KHP'!K2") -> 0 | G14: =KHPTH!A1 -> 0 | H14: =KHPTH!A2 -> 0 | M14: =KHPTH!B1 -> 0 | N14: =KHPTH!B2 -> 0 | S14: =KHPTH!C1 -> 0 | T14: =KHPTH!C2 -> 0 | Y14: =KHPTH!D1 -> 0 | Z14: =KHPTH!D2 -> 0 | AE14: =KHPTH!E1 -> 0 | AF14: =KHPTH!E2 -> 0 | AK14: =KHPTH!F1 -> 0 | AL14: =KHPTH!F2 -> 0 | AQ14: =KHPTH!G1 -> 0 | AR14: =KHPTH!G2 -> 0 | AW14: =KHPTH!H1 -> 0 | AX14: =KHPTH!H2 -> 0 | BC14: =KHPTH!I1 -> 0 | BD14: =KHPTH!I2 -> 0 | BI14: =KHPTH!J1 -> 0 | BJ14: =KHPTH!J2 -> 0 | BO14: =KHPTH!K1 -> 0 | BP14: =KHPTH!K2 -> 0 | BU14: =KHPTH!L1 -> 0 | BV14: =KHPTH!L2 -> 0 | BY14: =INDIRECT("'KHP'!R2") -> 0 | BZ14: =INDIRECT("KHP!L2") -> 0 | CA14: =BY14/C14 -> #DIV/0! | CB14: =BZ14/D14 -> #DIV/0!
A15: 6 | B15: KHO LPG MIỀN BẮC | C15: =INDIRECT("'KMB'!I2") -> 0 | D15: =INDIRECT("'KMB'!K2") -> 0 | G15: =KMBTH!A1 -> 0 | H15: =KMBTH!A2 -> 0 | M15: =KMBTH!B1 -> 0 | N15: =KMBTH!B2 -> 0 | S15: =KMBTH!C1 -> 0 | T15: =KMBTH!C2 -> 0 | Y15: =KMBTH!D1 -> 0 | Z15: =KMBTH!D2 -> 0 | AE15: =KMBTH!E1 -> 0 | AF15: =KMBTH!E2 -> 0 | AK15: =KMBTH!F1 -> 0 | AL15: =KMBTH!F2 -> 0 | AQ15: =KMBTH!G1 -> 0 | AR15: =KMBTH!G2 -> 0 | AW15: =KMBTH!H1 -> 0 | AX15: =KMBTH!H2 -> 0 | BC15: =KMBTH!I1 -> 0 | BD15: =KMBTH!I2 -> 0 | BI15: =KMBTH!J1 -> 0 | BJ15: =KMBTH!J2 -> 0 | BO15: =KMBTH!K1 -> 0 | BP15: =KMBTH!K2 -> 0 | BU15: =KMBTH!L1 -> 0 | BV15: =KMBTH!L2 -> 0 | BY15: =INDIRECT("'KMB'!R2") -> 0 | BZ15: =INDIRECT("KMB!L2") -> 0 | CA15: =BY15/C15 -> #DIV/0! | CB15: =BZ15/D15 -> #DIV/0!

Sheet mau2
A2: PHỤ LỤC I: KẾ HOẠCH BẢO DƯỠNG - SỬA CHỮA NĂM 20xy
A3: (Ban hành kèm theo Quyết định số …….…/QĐ-CNMB ngày …….…tháng …...… năm 20xy của Giám đốc Chi nhánh)
A5: TT | B5: NỘI DUNG CÔNG VIỆC | C5: Đơn vị | D5: Năm 20za | F5: KH 20xy
D6: Kế hoạch năm 20za | E6: Ước TH 20za | F6: Số lượng | G6: Thời gian thực hiện | H6: Đơn vị thực hiện | I6: Chi phí kế hoạch 20xy | J6: Năm phân bổ | K6: Chi phí phân bổ 2026 | L6: Cấp độ Công việc | M6: Chi phí cấp độ 1 | N6: Chi phí cấp độ 2 | O6: Ghi chú

Sheet mau1
A2: PHỤ LỤC I: KẾ HOẠCH BẢO DƯỠNG - SỬA CHỮA NĂM 20xy
A3: (Ban hành kèm theo Quyết định số …….…/QĐ-CNMB ngày …….…tháng …...… năm 20xy của Giám đốc Chi nhánh)
A5: TT | B5: NỘI DUNG CÔNG VIỆC | C5: Đơn vị | D5: Năm 20za | F5: KH 20xy
D6: Kế hoạch năm 20za | E6: Ước TH 20za | F6: Số lượng | G6: Thời gian thực hiện | H6: Đơn vị thực hiện | I6: Chi phí kế hoạch 20xy | J6: Năm phân bổ | K6: Chi phí phân bổ 2026 | L6: Cấp độ Công việc | M6: Chi phí cấp độ 1 | N6: Chi phí cấp độ 2 | O6: Ghi chú

Sheet mau3
A2: PHỤ LỤC I: KẾ HOẠCH BẢO DƯỠNG - SỬA CHỮA ĐIỀU CHỈNH NĂM 20xy
A3: (Ban hành kèm theo Quyết định số …….…/QĐ-CNMB ngày …….…tháng …...… năm 20xy của Giám đốc Chi nhánh)
A5: TT | B5: NỘI DUNG CÔNG VIỆC | C5: Đơn vị | D5: KH 20xy
D6: Chi phí đã thực hiện | E6: Số lượng | F6: Thời gian thực hiện | G6: Đơn vị thực hiện | H6: Chi phí kế hoạch 20xy | I6: Năm phân bổ | J6: Chi phí phân bổ 2026 | K6: Cấp độ Công việc | L6: Chi phí cấp độ 1 | M6: Chi phí cấp độ 2 | N6: Ghi chú

Sheet TONGHOP

Sheet XTTH
A1: =B1+C1 -> 0 | B1: =COUNTIF(C3:C400, ">0") -> 0 | C1: {=SUM(IF((D3:D400<>0)*(D3:D400<>"")*(D3:D400<>D2:D399), 1, 0))} -> 0 | E1: =F1+G1 -> 0 | F1: =COUNTIF(G3:G400, ">0") -> 0 | G1: {=SUM(IF((H3:H400<>0)*(H3:H400<>"")*(H3:H400<>H2:H399), 1, 0))} -> 0 | I1: =J1+K1 -> 0 | J1: =COUNTIF(K3:K400, ">0") -> 0 | K1: {=SUM(IF((L3:L400<>0)*(L3:L400<>"")*(L3:L400<>L2:L399), 1, 0))} -> 0 | M1: =N1+O1 -> 0 | N1: =COUNTIF(O3:O400, ">0") -> 0 | O1: {=SUM(IF((P3:P400<>0)*(P3:P400<>"")*(P3:P400<>P2:P399), 1, 0))} -> 0 | Q1: =R1+S1 -> 0 | R1: =COUNTIF(S3:S400, ">0") -> 0 | S1: {=SUM(IF((T3:T400<>0)*(T3:T400<>"")*(T3:T400<>T2:T399), 1, 0))} -> 0 | U1: =V1+W1 -> 0 | V1: =COUNTIF(W3:W400, ">0") -> 0 | W1: {=SUM(IF((X3:X400<>0)*(X3:X400<>"")*(X3:X400<>X2:X399), 1, 0))} -> 0 | Y1: =Z1+AA1 -> 0 | Z1: =COUNTIF(AA3:AA400, ">0") -> 0 | AA1: {=SUM(IF((AB3:AB400<>0)*(AB3:AB400<>"")*(AB3:AB400<>AB2:AB399), 1, 0))} -> 0 | AC1: =AD1+AE1 -> 0 | AD1: =COUNTIF(AE3:AE400, ">0") -> 0 | AE1: {=SUM(IF((AF3:AF400<>0)*(AF3:AF400<>"")*(AF3:AF400<>AF2:AF399), 1, 0))} -> 0 | AG1: =AH1+AI1 -> 0 | AH1: =COUNTIF(AI3:AI400, ">0") -> 0 | AI1: {=SUM(IF((AJ3:AJ400<>0)*(AJ3:AJ400<>"")*(AJ3:AJ400<>AJ2:AJ399), 1, 0))} -> 0 | AK1: =AL1+AM1 -> 0 | AL1: =COUNTIF(AM3:AM400, ">0") -> 0 | AM1: {=SUM(IF((AN3:AN400<>0)*(AN3:AN400<>"")*(AN3:AN400<>AN2:AN399), 1, 0))} -> 0 | AO1: =AP1+AQ1 -> 0 | AP1: =COUNTIF(AQ3:AQ400, ">0") -> 0 | AQ1: {=SUM(IF((AR3:AR400<>0)*(AR3:AR400<>"")*(AR3:AR400<>AR2:AR399), 1, 0))} -> 0 | AS1: =AT1+AU1 -> 0 | AT1: =COUNTIF(AU3:AU400, ">0") -> 0 | AU1: {=SUM(IF((AV3:AV400<>0)*(AV3:AV400<>"")*(AV3:AV400<>AV2:AV399), 1, 0))} -> 0
A2: =SUM(A3:A444) -> 0 | E2: =SUM(E3:E444) -> 0 | I2: =SUM(I3:I444) -> 0 | M2: =SUM(M3:M444) -> 0 | Q2: =SUM(Q3:Q444) -> 0 | U2: =SUM(U3:U444) -> 0 | Y2: =SUM(Y3:Y444) -> 0 | AC2: =SUM(AC3:AC444) -> 0 | AG2: =SUM(AG3:AG444) -> 0 | AK2: =SUM(AK3:AK444) -> 0 | AO2: =SUM(AO3:AO444) -> 0 | AS2: =SUM(AS3:AS444) -> 0
A3: =SUMPRODUCT((MONTH(CHOOSE({1,2,3,4},XT!U3,XT!Y3,XT!AC3,XT!AG3))=1)*(CHOOSE({1,2,3,4},XT!X3,XT!AB3,XT!AF3,XT!AJ3))) -> 0 | B3: =IFERROR(INDEX(CHOOSE({1,2,3,4}, DAY(XT!U3), DAY(XT!Y3), DAY(XT!AC3), DAY(XT!AG3)), MATCH(1, INDEX(--(MONTH(CHOOSE({1,2,3,4}, XT!U3,XT!Y3,XT!AC3,XT!AG3))=1), 0), 0)), "") -> 0 | C3: =IF(XT!$P3>0,B3,"") | D3: =IF(XT!$P3=0,B3,"") -> 0 | E3: =SUMPRODUCT((MONTH(CHOOSE({1,2,3,4},XT!U3,XT!Y3,XT!AC3,XT!AG3))=2)*(CHOOSE({1,2,3,4},XT!X3,XT!AB3,XT!AF3,XT!AJ3))) -> 0 | F3: =IFERROR(INDEX(CHOOSE({1,2,3,4}, DAY(XT!U3), DAY(XT!Y3), DAY(XT!AC3), DAY(XT!AG3)), MATCH(1, INDEX(--(MONTH(CHOOSE({1,2,3,4}, XT!U3,XT!Y3,XT!AC3,XT!AG3))=2), 0), 0)), "") | G3: =IF(XT!$P3>0,F3,"") | H3: =IF(XT!$P3=0,F3,"") | I3: =SUMPRODUCT((MONTH(CHOOSE({1,2,3,4},XT!U3,XT!Y3,XT!AC3,XT!AG3))=3)*(CHOOSE({1,2,3,4},XT!X3,XT!AB3,XT!AF3,XT!AJ3))) -> 0 | J3: =IFERROR(INDEX(CHOOSE({1,2,3,4}, DAY(XT!U3), DAY(XT!Y3), DAY(XT!AC3), DAY(XT!AG3)), MATCH(1, INDEX(--(MONTH(CHOOSE({1,2,3,4}, XT!U3,XT!Y3,XT!AC3,XT!AG3))=3), 0), 0)), "") | K3: =IF(XT!$P3>0,J3,"") | L3: =IF(XT!$P3=0,J3,"") | M3: =SUMPRODUCT((MONTH(CHOOSE({1,2,3,4},XT!U3,XT!Y3,XT!AC3,XT!AG3))=4)*(CHOOSE({1,2,3,4},XT!X3,XT!AB3,XT!AF3,XT!AJ3))) -> 0 | N3: =IFERROR(INDEX(CHOOSE({1,2,3,4}, DAY(XT!U3), DAY(XT!Y3), DAY(XT!AC3), DAY(XT!AG3)), MATCH(1, INDEX(--(MONTH(CHOOSE({1,2,3,4}, XT!U3,XT!Y3,XT!AC3,XT!AG3))=4), 0), 0)), "") | O3: =IF(XT!$P3>0,N3,"") | P3: =IF(XT!$P3=0,N3,"") | Q3: =SUMPRODUCT((MONTH(CHOOSE({1,2,3,4},XT!U3,XT!Y3,XT!AC3,XT!AG3))=5)*(CHOOSE({1,2,3,4},XT!X3,XT!AB3,XT!AF3,XT!AJ3))) -> 0 | R3: =IFERROR(INDEX(CHOOSE({1,2,3,4}, DAY(XT!U3), DAY(XT!Y3), DAY(XT!AC3), DAY(XT!AG3)), MATCH(1, INDEX(--(MONTH(CHOOSE({1,2,3,4}, XT!U3,XT!Y3,XT!AC3,XT!AG3))=5), 0), 0)), "") | S3: =IF(XT!$P3>0,R3,"") | T3: =IF(XT!$P3=0,R3,"") | U3: =SUMPRODUCT((MONTH(CHOOSE({1,2,3,4},XT!U3,XT!Y3,XT!AC3,XT!AG3))=6)*(CHOOSE({1,2,3,4},XT!X3,XT!AB3,XT!AF3,XT!AJ3))) -> 0 | V3: =IFERROR(INDEX(CHOOSE({1,2,3,4}, DAY(XT!U3), DAY(XT!Y3), DAY(XT!AC3), DAY(XT!AG3)), MATCH(1, INDEX(--(MONTH(CHOOSE({1,2,3,4}, XT!U3,XT!Y3,XT!AC3,XT!AG3))=6), 0), 0)), "") | W3: =IF(XT!$P3>0,V3,"") | X3: =IF(XT!$P3=0,V3,"") | Y3: =SUMPRODUCT((MONTH(CHOOSE({1,2,3,4},XT!U3,XT!Y3,XT!AC3,XT!AG3))=7)*(CHOOSE({1,2,3,4},XT!X3,XT!AB3,XT!AF3,XT!AJ3))) -> 0 | Z3: =IFERROR(INDEX(CHOOSE({1,2,3,4}, DAY(XT!U3), DAY(XT!Y3), DAY(XT!AC3), DAY(XT!AG3)), MATCH(1, INDEX(--(MONTH(CHOOSE({1,2,3,4}, XT!U3,XT!Y3,XT!AC3,XT!AG3))=7), 0), 0)), "") | AA3: =IF(XT!$P3>0,Z3,"") | AB3: =IF(XT!$P3=0,Z3,"") | AC3: =SUMPRODUCT((MONTH(CHOOSE({1,2,3,4},XT!U3,XT!Y3,XT!AC3,XT!AG3))=8)*(CHOOSE({1,2,3,4},XT!X3,XT!AB3,XT!AF3,XT!AJ3))) -> 0 | AD3: =IFERROR(INDEX(CHOOSE({1,2,3,4}, DAY(XT!U3), DAY(XT!Y3), DAY(XT!AC3), DAY(XT!AG3)), MATCH(1, INDEX(--(MONTH(CHOOSE({1,2,3,4}, XT!U3,XT!Y3,XT!AC3,XT!AG3))=8), 0), 0)), "") | AE3: =IF(XT!$P3>0,AD3,"") | AF3: =IF(XT!$P3=0,AD3,"") | AG3: =SUMPRODUCT((MONTH(CHOOSE({1,2,3,4},XT!U3,XT!Y3,XT!AC3,XT!AG3))=9)*(CHOOSE({1,2,3,4},XT!X3,XT!AB3,XT!AF3,XT!AJ3))) -> 0 | AH3: =IFERROR(INDEX(CHOOSE({1,2,3,4}, DAY(XT!U3), DAY(XT!Y3), DAY(XT!AC3), DAY(XT!AG3)), MATCH(1, INDEX(--(MONTH(CHOOSE({1,2,3,4}, XT!U3,XT!Y3,XT!AC3,XT!AG3))=9), 0), 0)), "") | AI3: =IF(XT!$P3>0,AH3,"") | AJ3: =IF(XT!$P3=0,AH3,"") | AK3: =SUMPRODUCT((MONTH(CHOOSE({1,2,3,4},XT!U3,XT!Y3,XT!AC3,XT!AG3))=10)*(CHOOSE({1,2,3,4},XT!X3,XT!AB3,XT!AF3,XT!AJ3))) -> 0 | AL3: =IFERROR(INDEX(CHOOSE({1,2,3,4}, DAY(XT!U3), DAY(XT!Y3), DAY(XT!AC3), DAY(XT!AG3)), MATCH(1, INDEX(--(MONTH(CHOOSE({1,2,3,4}, XT!U3,XT!Y3,XT!AC3,XT!AG3))=10), 0), 0)), "") | AM3: =IF(XT!$P3>0,AL3,"") | AN3: =IF(XT!$P3=0,AL3,"") | AO3: =SUMPRODUCT((MONTH(CHOOSE({1,2,3,4},XT!U3,XT!Y3,XT!AC3,XT!AG3))=11)*(CHOOSE({1,2,3,4},XT!X3,XT!AB3,XT!AF3,XT!AJ3))) -> 0 | AP3: =IFERROR(INDEX(CHOOSE({1,2,3,4}, DAY(XT!U3), DAY(XT!Y3), DAY(XT!AC3), DAY(XT!AG3)), MATCH(1, INDEX(--(MONTH(CHOOSE({1,2,3,4}, XT!U3,XT!Y3,XT!AC3,XT!AG3))=11), 0), 0)), "") | AQ3: =IF(XT!$P3>0,AP3,"") | AR3: =IF(XT!$P3=0,AP3,"") | AS3: =SUMPRODUCT((MONTH(CHOOSE({1,2,3,4},XT!U3,XT!Y3,XT!AC3,XT!AG3))=12)*(CHOOSE({1,2,3,4},XT!X3,XT!AB3,XT!AF3,XT!AJ3))) -> 0 | AT3: =IFERROR(INDEX(CHOOSE({1,2,3,4}, DAY(XT!U3), DAY(XT!Y3), DAY(XT!AC3), DAY(XT!AG3)), MATCH(1, INDEX(--(MONTH(CHOOSE({1,2,3,4}, XT!U3,XT!Y3,XT!AC3,XT!AG3))=12), 0), 0)), "") | AU3: =IF(XT!$P3>0,AT3,"") | AV3: =IF(XT!$P3=0,AT3,"")
A4: =SUMPRODUCT((MONTH(CHOOSE({1,2,3,4},XT!U4,XT!Y4,XT!AC4,XT!AG4))=1)*(CHOOSE({1,2,3,4},XT!X4,XT!AB4,XT!AF4,XT!AJ4))) -> 0 | B4: =IFERROR(INDEX(CHOOSE({1,2,3,4}, DAY(XT!U4), DAY(XT!Y4), DAY(XT!AC4), DAY(XT!AG4)), MATCH(1, INDEX(--(MONTH(CHOOSE({1,2,3,4}, XT!U4,XT!Y4,XT!AC4,XT!AG4))=1), 0), 0)), "") -> 0 | C4: =IF(XT!$P4>0,B4,"") | D4: =IF(XT!$P4=0,B4,"") -> 0 | E4: =SUMPRODUCT((MONTH(CHOOSE({1,2,3,4},XT!U4,XT!Y4,XT!AC4,XT!AG4))=2)*(CHOOSE({1,2,3,4},XT!X4,XT!AB4,XT!AF4,XT!AJ4))) -> 0 | F4: =IFERROR(INDEX(CHOOSE({1,2,3,4}, DAY(XT!U4), DAY(XT!Y4), DAY(XT!AC4), DAY(XT!AG4)), MATCH(1, INDEX(--(MONTH(CHOOSE({1,2,3,4}, XT!U4,XT!Y4,XT!AC4,XT!AG4))=2), 0), 0)), "") | G4: =IF(XT!$P4>0,F4,"") | H4: =IF(XT!$P4=0,F4,"") | I4: =SUMPRODUCT((MONTH(CHOOSE({1,2,3,4},XT!U4,XT!Y4,XT!AC4,XT!AG4))=3)*(CHOOSE({1,2,3,4},XT!X4,XT!AB4,XT!AF4,XT!AJ4))) -> 0 | J4: =IFERROR(INDEX(CHOOSE({1,2,3,4}, DAY(XT!U4), DAY(XT!Y4), DAY(XT!AC4), DAY(XT!AG4)), MATCH(1, INDEX(--(MONTH(CHOOSE({1,2,3,4}, XT!U4,XT!Y4,XT!AC4,XT!AG4))=3), 0), 0)), "") | K4: =IF(XT!$P4>0,J4,"") | L4: =IF(XT!$P4=0,J4,"") | M4: =SUMPRODUCT((MONTH(CHOOSE({1,2,3,4},XT!U4,XT!Y4,XT!AC4,XT!AG4))=4)*(CHOOSE({1,2,3,4},XT!X4,XT!AB4,XT!AF4,XT!AJ4))) -> 0 | N4: =IFERROR(INDEX(CHOOSE({1,2,3,4}, DAY(XT!U4), DAY(XT!Y4), DAY(XT!AC4), DAY(XT!AG4)), MATCH(1, INDEX(--(MONTH(CHOOSE({1,2,3,4}, XT!U4,XT!Y4,XT!AC4,XT!AG4))=4), 0), 0)), "") | O4: =IF(XT!$P4>0,N4,"") | P4: =IF(XT!$P4=0,N4,"") | Q4: =SUMPRODUCT((MONTH(CHOOSE({1,2,3,4},XT!U4,XT!Y4,XT!AC4,XT!AG4))=5)*(CHOOSE({1,2,3,4},XT!X4,XT!AB4,XT!AF4,XT!AJ4))) -> 0 | R4: =IFERROR(INDEX(CHOOSE({1,2,3,4}, DAY(XT!U4), DAY(XT!Y4), DAY(XT!AC4), DAY(XT!AG4)), MATCH(1, INDEX(--(MONTH(CHOOSE({1,2,3,4}, XT!U4,XT!Y4,XT!AC4,XT!AG4))=5), 0), 0)), "") | S4: =IF(XT!$P4>0,R4,"") | T4: =IF(XT!$P4=0,R4,"") | U4: =SUMPRODUCT((MONTH(CHOOSE({1,2,3,4},XT!U4,XT!Y4,XT!AC4,XT!AG4))=6)*(CHOOSE({1,2,3,4},XT!X4,XT!AB4,XT!AF4,XT!AJ4))) -> 0 | V4: =IFERROR(INDEX(CHOOSE({1,2,3,4}, DAY(XT!U4), DAY(XT!Y4), DAY(XT!AC4), DAY(XT!AG4)), MATCH(1, INDEX(--(MONTH(CHOOSE({1,2,3,4}, XT!U4,XT!Y4,XT!AC4,XT!AG4))=6), 0), 0)), "") | W4: =IF(XT!$P4>0,V4,"") | X4: =IF(XT!$P4=0,V4,"") | Y4: =SUMPRODUCT((MONTH(CHOOSE({1,2,3,4},XT!U4,XT!Y4,XT!AC4,XT!AG4))=7)*(CHOOSE({1,2,3,4},XT!X4,XT!AB4,XT!AF4,XT!AJ4))) -> 0 | Z4: =IFERROR(INDEX(CHOOSE({1,2,3,4}, DAY(XT!U4), DAY(XT!Y4), DAY(XT!AC4), DAY(XT!AG4)), MATCH(1, INDEX(--(MONTH(CHOOSE({1,2,3,4}, XT!U4,XT!Y4,XT!AC4,XT!AG4))=7), 0), 0)), "") | AA4: =IF(XT!$P4>0,Z4,"") | AB4: =IF(XT!$P4=0,Z4,"") | AC4: =SUMPRODUCT((MONTH(CHOOSE({1,2,3,4},XT!U4,XT!Y4,XT!AC4,XT!AG4))=8)*(CHOOSE({1,2,3,4},XT!X4,XT!AB4,XT!AF4,XT!AJ4))) -> 0 | AD4: =IFERROR(INDEX(CHOOSE({1,2,3,4}, DAY(XT!U4), DAY(XT!Y4), DAY(XT!AC4), DAY(XT!AG4)), MATCH(1, INDEX(--(MONTH(CHOOSE({1,2,3,4}, XT!U4,XT!Y4,XT!AC4,XT!AG4))=8), 0), 0)), "") | AE4: =IF(XT!$P4>0,AD4,"") | AF4: =IF(XT!$P4=0,AD4,"") | AG4: =SUMPRODUCT((MONTH(CHOOSE({1,2,3,4},XT!U4,XT!Y4,XT!AC4,XT!AG4))=9)*(CHOOSE({1,2,3,4},XT!X4,XT!AB4,XT!AF4,XT!AJ4))) -> 0 | AH4: =IFERROR(INDEX(CHOOSE({1,2,3,4}, DAY(XT!U4), DAY(XT!Y4), DAY(XT!AC4), DAY(XT!AG4)), MATCH(1, INDEX(--(MONTH(CHOOSE({1,2,3,4}, XT!U4,XT!Y4,XT!AC4,XT!AG4))=9), 0), 0)), "") | AI4: =IF(XT!$P4>0,AH4,"") | AJ4: =IF(XT!$P4=0,AH4,"") | AK4: =SUMPRODUCT((MONTH(CHOOSE({1,2,3,4},XT!U4,XT!Y4,XT!AC4,XT!AG4))=10)*(CHOOSE({1,2,3,4},XT!X4,XT!AB4,XT!AF4,XT!AJ4))) -> 0 | AL4: =IFERROR(INDEX(CHOOSE({1,2,3,4}, DAY(XT!U4), DAY(XT!Y4), DAY(XT!AC4), DAY(XT!AG4)), MATCH(1, INDEX(--(MONTH(CHOOSE({1,2,3,4}, XT!U4,XT!Y4,XT!AC4,XT!AG4))=10), 0), 0)), "") | AM4: =IF(XT!$P4>0,AL4,"") | AN4: =IF(XT!$P4=0,AL4,"") | AO4: =SUMPRODUCT((MONTH(CHOOSE({1,2,3,4},XT!U4,XT!Y4,XT!AC4,XT!AG4))=11)*(CHOOSE({1,2,3,4},XT!X4,XT!AB4,XT!AF4,XT!AJ4))) -> 0 | AP4: =IFERROR(INDEX(CHOOSE({1,2,3,4}, DAY(XT!U4), DAY(XT!Y4), DAY(XT!AC4), DAY(XT!AG4)), MATCH(1, INDEX(--(MONTH(CHOOSE({1,2,3,4}, XT!U4,XT!Y4,XT!AC4,XT!AG4))=11), 0), 0)), "") | AQ4: =IF(XT!$P4>0,AP4,"") | AR4: =IF(XT!$P4=0,AP4,"") | AS4: =SUMPRODUCT((MONTH(CHOOSE({1,2,3,4},XT!U4,XT!Y4,XT!AC4,XT!AG4))=12)*(CHOOSE({1,2,3,4},XT!X4,XT!AB4,XT!AF4,XT!AJ4))) -> 0 | AT4: =IFERROR(INDEX(CHOOSE({1,2,3,4}, DAY(XT!U4), DAY(XT!Y4), DAY(XT!AC4), DAY(XT!AG4)), MATCH(1, INDEX(--(MONTH(CHOOSE({1,2,3,4}, XT!U4,XT!Y4,XT!AC4,XT!AG4))=12), 0), 0)), "") | AU4: =IF(XT!$P4>0,AT4,"") | AV4: =IF(XT!$P4=0,AT4,"")
A5: =SUMPRODUCT((MONTH(CHOOSE({1,2,3,4},XT!U5,XT!Y5,XT!AC5,XT!AG5))=1)*(CHOOSE({1,2,3,4},XT!X5,XT!AB5,XT!AF5,XT!AJ5))) -> 0 | B5: =IFERROR(INDEX(CHOOSE({1,2,3,4}, DAY(XT!U5), DAY(XT!Y5), DAY(XT!AC5), DAY(XT!AG5)), MATCH(1, INDEX(--(MONTH(CHOOSE({1,2,3,4}, XT!U5,XT!Y5,XT!AC5,XT!AG5))=1), 0), 0)), "") -> 0 | C5: =IF(XT!$P5>0,B5,"") | D5: =IF(XT!$P5=0,B5,"") -> 0 | E5: =SUMPRODUCT((MONTH(CHOOSE({1,2,3,4},XT!U5,XT!Y5,XT!AC5,XT!AG5))=2)*(CHOOSE({1,2,3,4},XT!X5,XT!AB5,XT!AF5,XT!AJ5))) -> 0 | F5: =IFERROR(INDEX(CHOOSE({1,2,3,4}, DAY(XT!U5), DAY(XT!Y5), DAY(XT!AC5), DAY(XT!AG5)), MATCH(1, INDEX(--(MONTH(CHOOSE({1,2,3,4}, XT!U5,XT!Y5,XT!AC5,XT!AG5))=2), 0), 0)), "") | G5: =IF(XT!$P5>0,F5,"") | H5: =IF(XT!$P5=0,F5,"") | I5: =SUMPRODUCT((MONTH(CHOOSE({1,2,3,4},XT!U5,XT!Y5,XT!AC5,XT!AG5))=3)*(CHOOSE({1,2,3,4},XT!X5,XT!AB5,XT!AF5,XT!AJ5))) -> 0 | J5: =IFERROR(INDEX(CHOOSE({1,2,3,4}, DAY(XT!U5), DAY(XT!Y5), DAY(XT!AC5), DAY(XT!AG5)), MATCH(1, INDEX(--(MONTH(CHOOSE({1,2,3,4}, XT!U5,XT!Y5,XT!AC5,XT!AG5))=3), 0), 0)), "") | K5: =IF(XT!$P5>0,J5,"") | L5: =IF(XT!$P5=0,J5,"") | M5: =SUMPRODUCT((MONTH(CHOOSE({1,2,3,4},XT!U5,XT!Y5,XT!AC5,XT!AG5))=4)*(CHOOSE({1,2,3,4},XT!X5,XT!AB5,XT!AF5,XT!AJ5))) -> 0 | N5: =IFERROR(INDEX(CHOOSE({1,2,3,4}, DAY(XT!U5), DAY(XT!Y5), DAY(XT!AC5), DAY(XT!AG5)), MATCH(1, INDEX(--(MONTH(CHOOSE({1,2,3,4}, XT!U5,XT!Y5,XT!AC5,XT!AG5))=4), 0), 0)), "") | O5: =IF(XT!$P5>0,N5,"") | P5: =IF(XT!$P5=0,N5,"") | Q5: =SUMPRODUCT((MONTH(CHOOSE({1,2,3,4},XT!U5,XT!Y5,XT!AC5,XT!AG5))=5)*(CHOOSE({1,2,3,4},XT!X5,XT!AB5,XT!AF5,XT!AJ5))) -> 0 | R5: =IFERROR(INDEX(CHOOSE({1,2,3,4}, DAY(XT!U5), DAY(XT!Y5), DAY(XT!AC5), DAY(XT!AG5)), MATCH(1, INDEX(--(MONTH(CHOOSE({1,2,3,4}, XT!U5,XT!Y5,XT!AC5,XT!AG5))=5), 0), 0)), "") | S5: =IF(XT!$P5>0,R5,"") | T5: =IF(XT!$P5=0,R5,"") | U5: =SUMPRODUCT((MONTH(CHOOSE({1,2,3,4},XT!U5,XT!Y5,XT!AC5,XT!AG5))=6)*(CHOOSE({1,2,3,4},XT!X5,XT!AB5,XT!AF5,XT!AJ5))) -> 0 | V5: =IFERROR(INDEX(CHOOSE({1,2,3,4}, DAY(XT!U5), DAY(XT!Y5), DAY(XT!AC5), DAY(XT!AG5)), MATCH(1, INDEX(--(MONTH(CHOOSE({1,2,3,4}, XT!U5,XT!Y5,XT!AC5,XT!AG5))=6), 0), 0)), "") | W5: =IF(XT!$P5>0,V5,"") | X5: =IF(XT!$P5=0,V5,"") | Y5: =SUMPRODUCT((MONTH(CHOOSE({1,2,3,4},XT!U5,XT!Y5,XT!AC5,XT!AG5))=7)*(CHOOSE({1,2,3,4},XT!X5,XT!AB5,XT!AF5,XT!AJ5))) -> 0 | Z5: =IFERROR(INDEX(CHOOSE({1,2,3,4}, DAY(XT!U5), DAY(XT!Y5), DAY(XT!AC5), DAY(XT!AG5)), MATCH(1, INDEX(--(MONTH(CHOOSE({1,2,3,4}, XT!U5,XT!Y5,XT!AC5,XT!AG5))=7), 0), 0)), "") | AA5: =IF(XT!$P5>0,Z5,"") | AB5: =IF(XT!$P5=0,Z5,"") | AC5: =SUMPRODUCT((MONTH(CHOOSE({1,2,3,4},XT!U5,XT!Y5,XT!AC5,XT!AG5))=8)*(CHOOSE({1,2,3,4},XT!X5,XT!AB5,XT!AF5,XT!AJ5))) -> 0 | AD5: =IFERROR(INDEX(CHOOSE({1,2,3,4}, DAY(XT!U5), DAY(XT!Y5), DAY(XT!AC5), DAY(XT!AG5)), MATCH(1, INDEX(--(MONTH(CHOOSE({1,2,3,4}, XT!U5,XT!Y5,XT!AC5,XT!AG5))=8), 0), 0)), "") | AE5: =IF(XT!$P5>0,AD5,"") | AF5: =IF(XT!$P5=0,AD5,"") | AG5: =SUMPRODUCT((MONTH(CHOOSE({1,2,3,4},XT!U5,XT!Y5,XT!AC5,XT!AG5))=9)*(CHOOSE({1,2,3,4},XT!X5,XT!AB5,XT!AF5,XT!AJ5))) -> 0 | AH5: =IFERROR(INDEX(CHOOSE({1,2,3,4}, DAY(XT!U5), DAY(XT!Y5), DAY(XT!AC5), DAY(XT!AG5)), MATCH(1, INDEX(--(MONTH(CHOOSE({1,2,3,4}, XT!U5,XT!Y5,XT!AC5,XT!AG5))=9), 0), 0)), "") | AI5: =IF(XT!$P5>0,AH5,"") | AJ5: =IF(XT!$P5=0,AH5,"") | AK5: =SUMPRODUCT((MONTH(CHOOSE({1,2,3,4},XT!U5,XT!Y5,XT!AC5,XT!AG5))=10)*(CHOOSE({1,2,3,4},XT!X5,XT!AB5,XT!AF5,XT!AJ5))) -> 0 | AL5: =IFERROR(INDEX(CHOOSE({1,2,3,4}, DAY(XT!U5), DAY(XT!Y5), DAY(XT!AC5), DAY(XT!AG5)), MATCH(1, INDEX(--(MONTH(CHOOSE({1,2,3,4}, XT!U5,XT!Y5,XT!AC5,XT!AG5))=10), 0), 0)), "") | AM5: =IF(XT!$P5>0,AL5,"") | AN5: =IF(XT!$P5=0,AL5,"") | AO5: =SUMPRODUCT((MONTH(CHOOSE({1,2,3,4},XT!U5,XT!Y5,XT!AC5,XT!AG5))=11)*(CHOOSE({1,2,3,4},XT!X5,XT!AB5,XT!AF5,XT!AJ5))) -> 0 | AP5: =IFERROR(INDEX(CHOOSE({1,2,3,4}, DAY(XT!U5), DAY(XT!Y5), DAY(XT!AC5), DAY(XT!AG5)), MATCH(1, INDEX(--(MONTH(CHOOSE({1,2,3,4}, XT!U5,XT!Y5,XT!AC5,XT!AG5))=11), 0), 0)), "") | AQ5: =IF(XT!$P5>0,AP5,"") | AR5: =IF(XT!$P5=0,AP5,"") | AS5: =SUMPRODUCT((MONTH(CHOOSE({1,2,3,4},XT!U5,XT!Y5,XT!AC5,XT!AG5))=12)*(CHOOSE({1,2,3,4},XT!X5,XT!AB5,XT!AF5,XT!AJ5))) -> 0 | AT5: =IFERROR(INDEX(CHOOSE({1,2,3,4}, DAY(XT!U5), DAY(XT!Y5), DAY(XT!AC5), DAY(XT!AG5)), MATCH(1, INDEX(--(MONTH(CHOOSE({1,2,3,4}, XT!U5,XT!Y5,XT!AC5,XT!AG5))=12), 0), 0)), "") | AU5: =IF(XT!$P5>0,AT5,"") | AV5: =IF(XT!$P5=0,AT5,"")
A6: =SUMPRODUCT((MONTH(CHOOSE({1,2,3,4},XT!U6,XT!Y6,XT!AC6,XT!AG6))=1)*(CHOOSE({1,2,3,4},XT!X6,XT!AB6,XT!AF6,XT!AJ6))) -> 0 | B6: =IFERROR(INDEX(CHOOSE({1,2,3,4}, DAY(XT!U6), DAY(XT!Y6), DAY(XT!AC6), DAY(XT!AG6)), MATCH(1, INDEX(--(MONTH(CHOOSE({1,2,3,4}, XT!U6,XT!Y6,XT!AC6,XT!AG6))=1), 0), 0)), "") -> 0 | C6: =IF(XT!$P6>0,B6,"") | D6: =IF(XT!$P6=0,B6,"") -> 0 | E6: =SUMPRODUCT((MONTH(CHOOSE({1,2,3,4},XT!U6,XT!Y6,XT!AC6,XT!AG6))=2)*(CHOOSE({1,2,3,4},XT!X6,XT!AB6,XT!AF6,XT!AJ6))) -> 0 | F6: =IFERROR(INDEX(CHOOSE({1,2,3,4}, DAY(XT!U6), DAY(XT!Y6), DAY(XT!AC6), DAY(XT!AG6)), MATCH(1, INDEX(--(MONTH(CHOOSE({1,2,3,4}, XT!U6,XT!Y6,XT!AC6,XT!AG6))=2), 0), 0)), "") | G6: =IF(XT!$P6>0,F6,"") | H6: =IF(XT!$P6=0,F6,"") | I6: =SUMPRODUCT((MONTH(CHOOSE({1,2,3,4},XT!U6,XT!Y6,XT!AC6,XT!AG6))=3)*(CHOOSE({1,2,3,4},XT!X6,XT!AB6,XT!AF6,XT!AJ6))) -> 0 | J6: =IFERROR(INDEX(CHOOSE({1,2,3,4}, DAY(XT!U6), DAY(XT!Y6), DAY(XT!AC6), DAY(XT!AG6)), MATCH(1, INDEX(--(MONTH(CHOOSE({1,2,3,4}, XT!U6,XT!Y6,XT!AC6,XT!AG6))=3), 0), 0)), "") | K6: =IF(XT!$P6>0,J6,"") | L6: =IF(XT!$P6=0,J6,"") | M6: =SUMPRODUCT((MONTH(CHOOSE({1,2,3,4},XT!U6,XT!Y6,XT!AC6,XT!AG6))=4)*(CHOOSE({1,2,3,4},XT!X6,XT!AB6,XT!AF6,XT!AJ6))) -> 0 | N6: =IFERROR(INDEX(CHOOSE({1,2,3,4}, DAY(XT!U6), DAY(XT!Y6), DAY(XT!AC6), DAY(XT!AG6)), MATCH(1, INDEX(--(MONTH(CHOOSE({1,2,3,4}, XT!U6,XT!Y6,XT!AC6,XT!AG6))=4), 0), 0)), "") | O6: =IF(XT!$P6>0,N6,"") | P6: =IF(XT!$P6=0,N6,"") | Q6: =SUMPRODUCT((MONTH(CHOOSE({1,2,3,4},XT!U6,XT!Y6,XT!AC6,XT!AG6))=5)*(CHOOSE({1,2,3,4},XT!X6,XT!AB6,XT!AF6,XT!AJ6))) -> 0 | R6: =IFERROR(INDEX(CHOOSE({1,2,3,4}, DAY(XT!U6), DAY(XT!Y6), DAY(XT!AC6), DAY(XT!AG6)), MATCH(1, INDEX(--(MONTH(CHOOSE({1,2,3,4}, XT!U6,XT!Y6,XT!AC6,XT!AG6))=5), 0), 0)), "") | S6: =IF(XT!$P6>0,R6,"") | T6: =IF(XT!$P6=0,R6,"") | U6: =SUMPRODUCT((MONTH(CHOOSE({1,2,3,4},XT!U6,XT!Y6,XT!AC6,XT!AG6))=6)*(CHOOSE({1,2,3,4},XT!X6,XT!AB6,XT!AF6,XT!AJ6))) -> 0 | V6: =IFERROR(INDEX(CHOOSE({1,2,3,4}, DAY(XT!U6), DAY(XT!Y6), DAY(XT!AC6), DAY(XT!AG6)), MATCH(1, INDEX(--(MONTH(CHOOSE({1,2,3,4}, XT!U6,XT!Y6,XT!AC6,XT!AG6))=6), 0), 0)), "") | W6: =IF(XT!$P6>0,V6,"") | X6: =IF(XT!$P6=0,V6,"") | Y6: =SUMPRODUCT((MONTH(CHOOSE({1,2,3,4},XT!U6,XT!Y6,XT!AC6,XT!AG6))=7)*(CHOOSE({1,2,3,4},XT!X6,XT!AB6,XT!AF6,XT!AJ6))) -> 0 | Z6: =IFERROR(INDEX(CHOOSE({1,2,3,4}, DAY(XT!U6), DAY(XT!Y6), DAY(XT!AC6), DAY(XT!AG6)), MATCH(1, INDEX(--(MONTH(CHOOSE({1,2,3,4}, XT!U6,XT!Y6,XT!AC6,XT!AG6))=7), 0), 0)), "") | AA6: =IF(XT!$P6>0,Z6,"") | AB6: =IF(XT!$P6=0,Z6,"") | AC6: =SUMPRODUCT((MONTH(CHOOSE({1,2,3,4},XT!U6,XT!Y6,XT!AC6,XT!AG6))=8)*(CHOOSE({1,2,3,4},XT!X6,XT!AB6,XT!AF6,XT!AJ6))) -> 0 | AD6: =IFERROR(INDEX(CHOOSE({1,2,3,4}, DAY(XT!U6), DAY(XT!Y6), DAY(XT!AC6), DAY(XT!AG6)), MATCH(1, INDEX(--(MONTH(CHOOSE({1,2,3,4}, XT!U6,XT!Y6,XT!AC6,XT!AG6))=8), 0), 0)), "") | AE6: =IF(XT!$P6>0,AD6,"") | AF6: =IF(XT!$P6=0,AD6,"") | AG6: =SUMPRODUCT((MONTH(CHOOSE({1,2,3,4},XT!U6,XT!Y6,XT!AC6,XT!AG6))=9)*(CHOOSE({1,2,3,4},XT!X6,XT!AB6,XT!AF6,XT!AJ6))) -> 0 | AH6: =IFERROR(INDEX(CHOOSE({1,2,3,4}, DAY(XT!U6), DAY(XT!Y6), DAY(XT!AC6), DAY(XT!AG6)), MATCH(1, INDEX(--(MONTH(CHOOSE({1,2,3,4}, XT!U6,XT!Y6,XT!AC6,XT!AG6))=9), 0), 0)), "") | AI6: =IF(XT!$P6>0,AH6,"") | AJ6: =IF(XT!$P6=0,AH6,"") | AK6: =SUMPRODUCT((MONTH(CHOOSE({1,2,3,4},XT!U6,XT!Y6,XT!AC6,XT!AG6))=10)*(CHOOSE({1,2,3,4},XT!X6,XT!AB6,XT!AF6,XT!AJ6))) -> 0 | AL6: =IFERROR(INDEX(CHOOSE({1,2,3,4}, DAY(XT!U6), DAY(XT!Y6), DAY(XT!AC6), DAY(XT!AG6)), MATCH(1, INDEX(--(MONTH(CHOOSE({1,2,3,4}, XT!U6,XT!Y6,XT!AC6,XT!AG6))=10), 0), 0)), "") | AM6: =IF(XT!$P6>0,AL6,"") | AN6: =IF(XT!$P6=0,AL6,"") | AO6: =SUMPRODUCT((MONTH(CHOOSE({1,2,3,4},XT!U6,XT!Y6,XT!AC6,XT!AG6))=11)*(CHOOSE({1,2,3,4},XT!X6,XT!AB6,XT!AF6,XT!AJ6))) -> 0 | AP6: =IFERROR(INDEX(CHOOSE({1,2,3,4}, DAY(XT!U6), DAY(XT!Y6), DAY(XT!AC6), DAY(XT!AG6)), MATCH(1, INDEX(--(MONTH(CHOOSE({1,2,3,4}, XT!U6,XT!Y6,XT!AC6,XT!AG6))=11), 0), 0)), "") | AQ6: =IF(XT!$P6>0,AP6,"") | AR6: =IF(XT!$P6=0,AP6,"") | AS6: =SUMPRODUCT((MONTH(CHOOSE({1,2,3,4},XT!U6,XT!Y6,XT!AC6,XT!AG6))=12)*(CHOOSE({1,2,3,4},XT!X6,XT!AB6,XT!AF6,XT!AJ6))) -> 0 | AT6: =IFERROR(INDEX(CHOOSE({1,2,3,4}, DAY(XT!U6), DAY(XT!Y6), DAY(XT!AC6), DAY(XT!AG6)), MATCH(1, INDEX(--(MONTH(CHOOSE({1,2,3,4}, XT!U6,XT!Y6,XT!AC6,XT!AG6))=12), 0), 0)), "") | AU6: =IF(XT!$P6>0,AT6,"") | AV6: =IF(XT!$P6=0,AT6,"")
A7: =SUMPRODUCT((MONTH(CHOOSE({1,2,3,4},XT!U7,XT!Y7,XT!AC7,XT!AG7))=1)*(CHOOSE({1,2,3,4},XT!X7,XT!AB7,XT!AF7,XT!AJ7))) -> 0 | B7: =IFERROR(INDEX(CHOOSE({1,2,3,4}, DAY(XT!U7), DAY(XT!Y7), DAY(XT!AC7), DAY(XT!AG7)), MATCH(1, INDEX(--(MONTH(CHOOSE({1,2,3,4}, XT!U7,XT!Y7,XT!AC7,XT!AG7))=1), 0), 0)), "") -> 0 | C7: =IF(XT!$P7>0,B7,"") | D7: =IF(XT!$P7=0,B7,"") -> 0 | E7: =SUMPRODUCT((MONTH(CHOOSE({1,2,3,4},XT!U7,XT!Y7,XT!AC7,XT!AG7))=2)*(CHOOSE({1,2,3,4},XT!X7,XT!AB7,XT!AF7,XT!AJ7))) -> 0 | F7: =IFERROR(INDEX(CHOOSE({1,2,3,4}, DAY(XT!U7), DAY(XT!Y7), DAY(XT!AC7), DAY(XT!AG7)), MATCH(1, INDEX(--(MONTH(CHOOSE({1,2,3,4}, XT!U7,XT!Y7,XT!AC7,XT!AG7))=2), 0), 0)), "") | G7: =IF(XT!$P7>0,F7,"") | H7: =IF(XT!$P7=0,F7,"") | I7: =SUMPRODUCT((MONTH(CHOOSE({1,2,3,4},XT!U7,XT!Y7,XT!AC7,XT!AG7))=3)*(CHOOSE({1,2,3,4},XT!X7,XT!AB7,XT!AF7,XT!AJ7))) -> 0 | J7: =IFERROR(INDEX(CHOOSE({1,2,3,4}, DAY(XT!U7), DAY(XT!Y7), DAY(XT!AC7), DAY(XT!AG7)), MATCH(1, INDEX(--(MONTH(CHOOSE({1,2,3,4}, XT!U7,XT!Y7,XT!AC7,XT!AG7))=3), 0), 0)), "") | K7: =IF(XT!$P7>0,J7,"") | L7: =IF(XT!$P7=0,J7,"") | M7: =SUMPRODUCT((MONTH(CHOOSE({1,2,3,4},XT!U7,XT!Y7,XT!AC7,XT!AG7))=4)*(CHOOSE({1,2,3,4},XT!X7,XT!AB7,XT!AF7,XT!AJ7))) -> 0 | N7: =IFERROR(INDEX(CHOOSE({1,2,3,4}, DAY(XT!U7), DAY(XT!Y7), DAY(XT!AC7), DAY(XT!AG7)), MATCH(1, INDEX(--(MONTH(CHOOSE({1,2,3,4}, XT!U7,XT!Y7,XT!AC7,XT!AG7))=4), 0), 0)), "") | O7: =IF(XT!$P7>0,N7,"") | P7: =IF(XT!$P7=0,N7,"") | Q7: =SUMPRODUCT((MONTH(CHOOSE({1,2,3,4},XT!U7,XT!Y7,XT!AC7,XT!AG7))=5)*(CHOOSE({1,2,3,4},XT!X7,XT!AB7,XT!AF7,XT!AJ7))) -> 0 | R7: =IFERROR(INDEX(CHOOSE({1,2,3,4}, DAY(XT!U7), DAY(XT!Y7), DAY(XT!AC7), DAY(XT!AG7)), MATCH(1, INDEX(--(MONTH(CHOOSE({1,2,3,4}, XT!U7,XT!Y7,XT!AC7,XT!AG7))=5), 0), 0)), "") | S7: =IF(XT!$P7>0,R7,"") | T7: =IF(XT!$P7=0,R7,"") | U7: =SUMPRODUCT((MONTH(CHOOSE({1,2,3,4},XT!U7,XT!Y7,XT!AC7,XT!AG7))=6)*(CHOOSE({1,2,3,4},XT!X7,XT!AB7,XT!AF7,XT!AJ7))) -> 0 | V7: =IFERROR(INDEX(CHOOSE({1,2,3,4}, DAY(XT!U7), DAY(XT!Y7), DAY(XT!AC7), DAY(XT!AG7)), MATCH(1, INDEX(--(MONTH(CHOOSE({1,2,3,4}, XT!U7,XT!Y7,XT!AC7,XT!AG7))=6), 0), 0)), "") | W7: =IF(XT!$P7>0,V7,"") | X7: =IF(XT!$P7=0,V7,"") | Y7: =SUMPRODUCT((MONTH(CHOOSE({1,2,3,4},XT!U7,XT!Y7,XT!AC7,XT!AG7))=7)*(CHOOSE({1,2,3,4},XT!X7,XT!AB7,XT!AF7,XT!AJ7))) -> 0 | Z7: =IFERROR(INDEX(CHOOSE({1,2,3,4}, DAY(XT!U7), DAY(XT!Y7), DAY(XT!AC7), DAY(XT!AG7)), MATCH(1, INDEX(--(MONTH(CHOOSE({1,2,3,4}, XT!U7,XT!Y7,XT!AC7,XT!AG7))=7), 0), 0)), "") | AA7: =IF(XT!$P7>0,Z7,"") | AB7: =IF(XT!$P7=0,Z7,"") | AC7: =SUMPRODUCT((MONTH(CHOOSE({1,2,3,4},XT!U7,XT!Y7,XT!AC7,XT!AG7))=8)*(CHOOSE({1,2,3,4},XT!X7,XT!AB7,XT!AF7,XT!AJ7))) -> 0 | AD7: =IFERROR(INDEX(CHOOSE({1,2,3,4}, DAY(XT!U7), DAY(XT!Y7), DAY(XT!AC7), DAY(XT!AG7)), MATCH(1, INDEX(--(MONTH(CHOOSE({1,2,3,4}, XT!U7,XT!Y7,XT!AC7,XT!AG7))=8), 0), 0)), "") | AE7: =IF(XT!$P7>0,AD7,"") | AF7: =IF(XT!$P7=0,AD7,"") | AG7: =SUMPRODUCT((MONTH(CHOOSE({1,2,3,4},XT!U7,XT!Y7,XT!AC7,XT!AG7))=9)*(CHOOSE({1,2,3,4},XT!X7,XT!AB7,XT!AF7,XT!AJ7))) -> 0 | AH7: =IFERROR(INDEX(CHOOSE({1,2,3,4}, DAY(XT!U7), DAY(XT!Y7), DAY(XT!AC7), DAY(XT!AG7)), MATCH(1, INDEX(--(MONTH(CHOOSE({1,2,3,4}, XT!U7,XT!Y7,XT!AC7,XT!AG7))=9), 0), 0)), "") | AI7: =IF(XT!$P7>0,AH7,"") | AJ7: =IF(XT!$P7=0,AH7,"") | AK7: =SUMPRODUCT((MONTH(CHOOSE({1,2,3,4},XT!U7,XT!Y7,XT!AC7,XT!AG7))=10)*(CHOOSE({1,2,3,4},XT!X7,XT!AB7,XT!AF7,XT!AJ7))) -> 0 | AL7: =IFERROR(INDEX(CHOOSE({1,2,3,4}, DAY(XT!U7), DAY(XT!Y7), DAY(XT!AC7), DAY(XT!AG7)), MATCH(1, INDEX(--(MONTH(CHOOSE({1,2,3,4}, XT!U7,XT!Y7,XT!AC7,XT!AG7))=10), 0), 0)), "") | AM7: =IF(XT!$P7>0,AL7,"") | AN7: =IF(XT!$P7=0,AL7,"") | AO7: =SUMPRODUCT((MONTH(CHOOSE({1,2,3,4},XT!U7,XT!Y7,XT!AC7,XT!AG7))=11)*(CHOOSE({1,2,3,4},XT!X7,XT!AB7,XT!AF7,XT!AJ7))) -> 0 | AP7: =IFERROR(INDEX(CHOOSE({1,2,3,4}, DAY(XT!U7), DAY(XT!Y7), DAY(XT!AC7), DAY(XT!AG7)), MATCH(1, INDEX(--(MONTH(CHOOSE({1,2,3,4}, XT!U7,XT!Y7,XT!AC7,XT!AG7))=11), 0), 0)), "") | AQ7: =IF(XT!$P7>0,AP7,"") | AR7: =IF(XT!$P7=0,AP7,"") | AS7: =SUMPRODUCT((MONTH(CHOOSE({1,2,3,4},XT!U7,XT!Y7,XT!AC7,XT!AG7))=12)*(CHOOSE({1,2,3,4},XT!X7,XT!AB7,XT!AF7,XT!AJ7))) -> 0 | AT7: =IFERROR(INDEX(CHOOSE({1,2,3,4}, DAY(XT!U7), DAY(XT!Y7), DAY(XT!AC7), DAY(XT!AG7)), MATCH(1, INDEX(--(MONTH(CHOOSE({1,2,3,4}, XT!U7,XT!Y7,XT!AC7,XT!AG7))=12), 0), 0)), "") | AU7: =IF(XT!$P7>0,AT7,"") | AV7: =IF(XT!$P7=0,AT7,"")
A8: =SUMPRODUCT((MONTH(CHOOSE({1,2,3,4},XT!U8,XT!Y8,XT!AC8,XT!AG8))=1)*(CHOOSE({1,2,3,4},XT!X8,XT!AB8,XT!AF8,XT!AJ8))) -> 0 | B8: =IFERROR(INDEX(CHOOSE({1,2,3,4}, DAY(XT!U8), DAY(XT!Y8), DAY(XT!AC8), DAY(XT!AG8)), MATCH(1, INDEX(--(MONTH(CHOOSE({1,2,3,4}, XT!U8,XT!Y8,XT!AC8,XT!AG8))=1), 0), 0)), "") -> 0 | C8: =IF(XT!$P8>0,B8,"") | D8: =IF(XT!$P8=0,B8,"") -> 0 | E8: =SUMPRODUCT((MONTH(CHOOSE({1,2,3,4},XT!U8,XT!Y8,XT!AC8,XT!AG8))=2)*(CHOOSE({1,2,3,4},XT!X8,XT!AB8,XT!AF8,XT!AJ8))) -> 0 | F8: =IFERROR(INDEX(CHOOSE({1,2,3,4}, DAY(XT!U8), DAY(XT!Y8), DAY(XT!AC8), DAY(XT!AG8)), MATCH(1, INDEX(--(MONTH(CHOOSE({1,2,3,4}, XT!U8,XT!Y8,XT!AC8,XT!AG8))=2), 0), 0)), "") | G8: =IF(XT!$P8>0,F8,"") | H8: =IF(XT!$P8=0,F8,"") | I8: =SUMPRODUCT((MONTH(CHOOSE({1,2,3,4},XT!U8,XT!Y8,XT!AC8,XT!AG8))=3)*(CHOOSE({1,2,3,4},XT!X8,XT!AB8,XT!AF8,XT!AJ8))) -> 0 | J8: =IFERROR(INDEX(CHOOSE({1,2,3,4}, DAY(XT!U8), DAY(XT!Y8), DAY(XT!AC8), DAY(XT!AG8)), MATCH(1, INDEX(--(MONTH(CHOOSE({1,2,3,4}, XT!U8,XT!Y8,XT!AC8,XT!AG8))=3), 0), 0)), "") | K8: =IF(XT!$P8>0,J8,"") | L8: =IF(XT!$P8=0,J8,"") | M8: =SUMPRODUCT((MONTH(CHOOSE({1,2,3,4},XT!U8,XT!Y8,XT!AC8,XT!AG8))=4)*(CHOOSE({1,2,3,4},XT!X8,XT!AB8,XT!AF8,XT!AJ8))) -> 0 | N8: =IFERROR(INDEX(CHOOSE({1,2,3,4}, DAY(XT!U8), DAY(XT!Y8), DAY(XT!AC8), DAY(XT!AG8)), MATCH(1, INDEX(--(MONTH(CHOOSE({1,2,3,4}, XT!U8,XT!Y8,XT!AC8,XT!AG8))=4), 0), 0)), "") | O8: =IF(XT!$P8>0,N8,"") | P8: =IF(XT!$P8=0,N8,"") | Q8: =SUMPRODUCT((MONTH(CHOOSE({1,2,3,4},XT!U8,XT!Y8,XT!AC8,XT!AG8))=5)*(CHOOSE({1,2,3,4},XT!X8,XT!AB8,XT!AF8,XT!AJ8))) -> 0 | R8: =IFERROR(INDEX(CHOOSE({1,2,3,4}, DAY(XT!U8), DAY(XT!Y8), DAY(XT!AC8), DAY(XT!AG8)), MATCH(1, INDEX(--(MONTH(CHOOSE({1,2,3,4}, XT!U8,XT!Y8,XT!AC8,XT!AG8))=5), 0), 0)), "") | S8: =IF(XT!$P8>0,R8,"") | T8: =IF(XT!$P8=0,R8,"") | U8: =SUMPRODUCT((MONTH(CHOOSE({1,2,3,4},XT!U8,XT!Y8,XT!AC8,XT!AG8))=6)*(CHOOSE({1,2,3,4},XT!X8,XT!AB8,XT!AF8,XT!AJ8))) -> 0 | V8: =IFERROR(INDEX(CHOOSE({1,2,3,4}, DAY(XT!U8), DAY(XT!Y8), DAY(XT!AC8), DAY(XT!AG8)), MATCH(1, INDEX(--(MONTH(CHOOSE({1,2,3,4}, XT!U8,XT!Y8,XT!AC8,XT!AG8))=6), 0), 0)), "") | W8: =IF(XT!$P8>0,V8,"") | X8: =IF(XT!$P8=0,V8,"") | Y8: =SUMPRODUCT((MONTH(CHOOSE({1,2,3,4},XT!U8,XT!Y8,XT!AC8,XT!AG8))=7)*(CHOOSE({1,2,3,4},XT!X8,XT!AB8,XT!AF8,XT!AJ8))) -> 0 | Z8: =IFERROR(INDEX(CHOOSE({1,2,3,4}, DAY(XT!U8), DAY(XT!Y8), DAY(XT!AC8), DAY(XT!AG8)), MATCH(1, INDEX(--(MONTH(CHOOSE({1,2,3,4}, XT!U8,XT!Y8,XT!AC8,XT!AG8))=7), 0), 0)), "") | AA8: =IF(XT!$P8>0,Z8,"") | AB8: =IF(XT!$P8=0,Z8,"") | AC8: =SUMPRODUCT((MONTH(CHOOSE({1,2,3,4},XT!U8,XT!Y8,XT!AC8,XT!AG8))=8)*(CHOOSE({1,2,3,4},XT!X8,XT!AB8,XT!AF8,XT!AJ8))) -> 0 | AD8: =IFERROR(INDEX(CHOOSE({1,2,3,4}, DAY(XT!U8), DAY(XT!Y8), DAY(XT!AC8), DAY(XT!AG8)), MATCH(1, INDEX(--(MONTH(CHOOSE({1,2,3,4}, XT!U8,XT!Y8,XT!AC8,XT!AG8))=8), 0), 0)), "") | AE8: =IF(XT!$P8>0,AD8,"") | AF8: =IF(XT!$P8=0,AD8,"") | AG8: =SUMPRODUCT((MONTH(CHOOSE({1,2,3,4},XT!U8,XT!Y8,XT!AC8,XT!AG8))=9)*(CHOOSE({1,2,3,4},XT!X8,XT!AB8,XT!AF8,XT!AJ8))) -> 0 | AH8: =IFERROR(INDEX(CHOOSE({1,2,3,4}, DAY(XT!U8), DAY(XT!Y8), DAY(XT!AC8), DAY(XT!AG8)), MATCH(1, INDEX(--(MONTH(CHOOSE({1,2,3,4}, XT!U8,XT!Y8,XT!AC8,XT!AG8))=9), 0), 0)), "") | AI8: =IF(XT!$P8>0,AH8,"") | AJ8: =IF(XT!$P8=0,AH8,"") | AK8: =SUMPRODUCT((MONTH(CHOOSE({1,2,3,4},XT!U8,XT!Y8,XT!AC8,XT!AG8))=10)*(CHOOSE({1,2,3,4},XT!X8,XT!AB8,XT!AF8,XT!AJ8))) -> 0 | AL8: =IFERROR(INDEX(CHOOSE({1,2,3,4}, DAY(XT!U8), DAY(XT!Y8), DAY(XT!AC8), DAY(XT!AG8)), MATCH(1, INDEX(--(MONTH(CHOOSE({1,2,3,4}, XT!U8,XT!Y8,XT!AC8,XT!AG8))=10), 0), 0)), "") | AM8: =IF(XT!$P8>0,AL8,"") | AN8: =IF(XT!$P8=0,AL8,"") | AO8: =SUMPRODUCT((MONTH(CHOOSE({1,2,3,4},XT!U8,XT!Y8,XT!AC8,XT!AG8))=11)*(CHOOSE({1,2,3,4},XT!X8,XT!AB8,XT!AF8,XT!AJ8))) -> 0 | AP8: =IFERROR(INDEX(CHOOSE({1,2,3,4}, DAY(XT!U8), DAY(XT!Y8), DAY(XT!AC8), DAY(XT!AG8)), MATCH(1, INDEX(--(MONTH(CHOOSE({1,2,3,4}, XT!U8,XT!Y8,XT!AC8,XT!AG8))=11), 0), 0)), "") | AQ8: =IF(XT!$P8>0,AP8,"") | AR8: =IF(XT!$P8=0,AP8,"") | AS8: =SUMPRODUCT((MONTH(CHOOSE({1,2,3,4},XT!U8,XT!Y8,XT!AC8,XT!AG8))=12)*(CHOOSE({1,2,3,4},XT!X8,XT!AB8,XT!AF8,XT!AJ8))) -> 0 | AT8: =IFERROR(INDEX(CHOOSE({1,2,3,4}, DAY(XT!U8), DAY(XT!Y8), DAY(XT!AC8), DAY(XT!AG8)), MATCH(1, INDEX(--(MONTH(CHOOSE({1,2,3,4}, XT!U8,XT!Y8,XT!AC8,XT!AG8))=12), 0), 0)), "") | AU8: =IF(XT!$P8>0,AT8,"") | AV8: =IF(XT!$P8=0,AT8,"")
A9: =SUMPRODUCT((MONTH(CHOOSE({1,2,3,4},XT!U9,XT!Y9,XT!AC9,XT!AG9))=1)*(CHOOSE({1,2,3,4},XT!X9,XT!AB9,XT!AF9,XT!AJ9))) -> 0 | B9: =IFERROR(INDEX(CHOOSE({1,2,3,4}, DAY(XT!U9), DAY(XT!Y9), DAY(XT!AC9), DAY(XT!AG9)), MATCH(1, INDEX(--(MONTH(CHOOSE({1,2,3,4}, XT!U9,XT!Y9,XT!AC9,XT!AG9))=1), 0), 0)), "") -> 0 | C9: =IF(XT!$P9>0,B9,"") | D9: =IF(XT!$P9=0,B9,"") -> 0 | E9: =SUMPRODUCT((MONTH(CHOOSE({1,2,3,4},XT!U9,XT!Y9,XT!AC9,XT!AG9))=2)*(CHOOSE({1,2,3,4},XT!X9,XT!AB9,XT!AF9,XT!AJ9))) -> 0 | F9: =IFERROR(INDEX(CHOOSE({1,2,3,4}, DAY(XT!U9), DAY(XT!Y9), DAY(XT!AC9), DAY(XT!AG9)), MATCH(1, INDEX(--(MONTH(CHOOSE({1,2,3,4}, XT!U9,XT!Y9,XT!AC9,XT!AG9))=2), 0), 0)), "") | G9: =IF(XT!$P9>0,F9,"") | H9: =IF(XT!$P9=0,F9,"") | I9: =SUMPRODUCT((MONTH(CHOOSE({1,2,3,4},XT!U9,XT!Y9,XT!AC9,XT!AG9))=3)*(CHOOSE({1,2,3,4},XT!X9,XT!AB9,XT!AF9,XT!AJ9))) -> 0 | J9: =IFERROR(INDEX(CHOOSE({1,2,3,4}, DAY(XT!U9), DAY(XT!Y9), DAY(XT!AC9), DAY(XT!AG9)), MATCH(1, INDEX(--(MONTH(CHOOSE({1,2,3,4}, XT!U9,XT!Y9,XT!AC9,XT!AG9))=3), 0), 0)), "") | K9: =IF(XT!$P9>0,J9,"") | L9: =IF(XT!$P9=0,J9,"") | M9: =SUMPRODUCT((MONTH(CHOOSE({1,2,3,4},XT!U9,XT!Y9,XT!AC9,XT!AG9))=4)*(CHOOSE({1,2,3,4},XT!X9,XT!AB9,XT!AF9,XT!AJ9))) -> 0 | N9: =IFERROR(INDEX(CHOOSE({1,2,3,4}, DAY(XT!U9), DAY(XT!Y9), DAY(XT!AC9), DAY(XT!AG9)), MATCH(1, INDEX(--(MONTH(CHOOSE({1,2,3,4}, XT!U9,XT!Y9,XT!AC9,XT!AG9))=4), 0), 0)), "") | O9: =IF(XT!$P9>0,N9,"") | P9: =IF(XT!$P9=0,N9,"") | Q9: =SUMPRODUCT((MONTH(CHOOSE({1,2,3,4},XT!U9,XT!Y9,XT!AC9,XT!AG9))=5)*(CHOOSE({1,2,3,4},XT!X9,XT!AB9,XT!AF9,XT!AJ9))) -> 0 | R9: =IFERROR(INDEX(CHOOSE({1,2,3,4}, DAY(XT!U9), DAY(XT!Y9), DAY(XT!AC9), DAY(XT!AG9)), MATCH(1, INDEX(--(MONTH(CHOOSE({1,2,3,4}, XT!U9,XT!Y9,XT!AC9,XT!AG9))=5), 0), 0)), "") | S9: =IF(XT!$P9>0,R9,"") | T9: =IF(XT!$P9=0,R9,"") | U9: =SUMPRODUCT((MONTH(CHOOSE({1,2,3,4},XT!U9,XT!Y9,XT!AC9,XT!AG9))=6)*(CHOOSE({1,2,3,4},XT!X9,XT!AB9,XT!AF9,XT!AJ9))) -> 0 | V9: =IFERROR(INDEX(CHOOSE({1,2,3,4}, DAY(XT!U9), DAY(XT!Y9), DAY(XT!AC9), DAY(XT!AG9)), MATCH(1, INDEX(--(MONTH(CHOOSE({1,2,3,4}, XT!U9,XT!Y9,XT!AC9,XT!AG9))=6), 0), 0)), "") | W9: =IF(XT!$P9>0,V9,"") | X9: =IF(XT!$P9=0,V9,"") | Y9: =SUMPRODUCT((MONTH(CHOOSE({1,2,3,4},XT!U9,XT!Y9,XT!AC9,XT!AG9))=7)*(CHOOSE({1,2,3,4},XT!X9,XT!AB9,XT!AF9,XT!AJ9))) -> 0 | Z9: =IFERROR(INDEX(CHOOSE({1,2,3,4}, DAY(XT!U9), DAY(XT!Y9), DAY(XT!AC9), DAY(XT!AG9)), MATCH(1, INDEX(--(MONTH(CHOOSE({1,2,3,4}, XT!U9,XT!Y9,XT!AC9,XT!AG9))=7), 0), 0)), "") | AA9: =IF(XT!$P9>0,Z9,"") | AB9: =IF(XT!$P9=0,Z9,"") | AC9: =SUMPRODUCT((MONTH(CHOOSE({1,2,3,4},XT!U9,XT!Y9,XT!AC9,XT!AG9))=8)*(CHOOSE({1,2,3,4},XT!X9,XT!AB9,XT!AF9,XT!AJ9))) -> 0 | AD9: =IFERROR(INDEX(CHOOSE({1,2,3,4}, DAY(XT!U9), DAY(XT!Y9), DAY(XT!AC9), DAY(XT!AG9)), MATCH(1, INDEX(--(MONTH(CHOOSE({1,2,3,4}, XT!U9,XT!Y9,XT!AC9,XT!AG9))=8), 0), 0)), "") | AE9: =IF(XT!$P9>0,AD9,"") | AF9: =IF(XT!$P9=0,AD9,"") | AG9: =SUMPRODUCT((MONTH(CHOOSE({1,2,3,4},XT!U9,XT!Y9,XT!AC9,XT!AG9))=9)*(CHOOSE({1,2,3,4},XT!X9,XT!AB9,XT!AF9,XT!AJ9))) -> 0 | AH9: =IFERROR(INDEX(CHOOSE({1,2,3,4}, DAY(XT!U9), DAY(XT!Y9), DAY(XT!AC9), DAY(XT!AG9)), MATCH(1, INDEX(--(MONTH(CHOOSE({1,2,3,4}, XT!U9,XT!Y9,XT!AC9,XT!AG9))=9), 0), 0)), "") | AI9: =IF(XT!$P9>0,AH9,"") | AJ9: =IF(XT!$P9=0,AH9,"") | AK9: =SUMPRODUCT((MONTH(CHOOSE({1,2,3,4},XT!U9,XT!Y9,XT!AC9,XT!AG9))=10)*(CHOOSE({1,2,3,4},XT!X9,XT!AB9,XT!AF9,XT!AJ9))) -> 0 | AL9: =IFERROR(INDEX(CHOOSE({1,2,3,4}, DAY(XT!U9), DAY(XT!Y9), DAY(XT!AC9), DAY(XT!AG9)), MATCH(1, INDEX(--(MONTH(CHOOSE({1,2,3,4}, XT!U9,XT!Y9,XT!AC9,XT!AG9))=10), 0), 0)), "") | AM9: =IF(XT!$P9>0,AL9,"") | AN9: =IF(XT!$P9=0,AL9,"") | AO9: =SUMPRODUCT((MONTH(CHOOSE({1,2,3,4},XT!U9,XT!Y9,XT!AC9,XT!AG9))=11)*(CHOOSE({1,2,3,4},XT!X9,XT!AB9,XT!AF9,XT!AJ9))) -> 0 | AP9: =IFERROR(INDEX(CHOOSE({1,2,3,4}, DAY(XT!U9), DAY(XT!Y9), DAY(XT!AC9), DAY(XT!AG9)), MATCH(1, INDEX(--(MONTH(CHOOSE({1,2,3,4}, XT!U9,XT!Y9,XT!AC9,XT!AG9))=11), 0), 0)), "") | AQ9: =IF(XT!$P9>0,AP9,"") | AR9: =IF(XT!$P9=0,AP9,"") | AS9: =SUMPRODUCT((MONTH(CHOOSE({1,2,3,4},XT!U9,XT!Y9,XT!AC9,XT!AG9))=12)*(CHOOSE({1,2,3,4},XT!X9,XT!AB9,XT!AF9,XT!AJ9))) -> 0 | AT9: =IFERROR(INDEX(CHOOSE({1,2,3,4}, DAY(XT!U9), DAY(XT!Y9), DAY(XT!AC9), DAY(XT!AG9)), MATCH(1, INDEX(--(MONTH(CHOOSE({1,2,3,4}, XT!U9,XT!Y9,XT!AC9,XT!AG9))=12), 0), 0)), "") | AU9: =IF(XT!$P9>0,AT9,"") | AV9: =IF(XT!$P9=0,AT9,"")
A10: =SUMPRODUCT((MONTH(CHOOSE({1,2,3,4},XT!U10,XT!Y10,XT!AC10,XT!AG10))=1)*(CHOOSE({1,2,3,4},XT!X10,XT!AB10,XT!AF10,XT!AJ10))) -> 0 | B10: =IFERROR(INDEX(CHOOSE({1,2,3,4}, DAY(XT!U10), DAY(XT!Y10), DAY(XT!AC10), DAY(XT!AG10)), MATCH(1, INDEX(--(MONTH(CHOOSE({1,2,3,4}, XT!U10,XT!Y10,XT!AC10,XT!AG10))=1), 0), 0)), "") -> 0 | C10: =IF(XT!$P10>0,B10,"") | D10: =IF(XT!$P10=0,B10,"") -> 0 | E10: =SUMPRODUCT((MONTH(CHOOSE({1,2,3,4},XT!U10,XT!Y10,XT!AC10,XT!AG10))=2)*(CHOOSE({1,2,3,4},XT!X10,XT!AB10,XT!AF10,XT!AJ10))) -> 0 | F10: =IFERROR(INDEX(CHOOSE({1,2,3,4}, DAY(XT!U10), DAY(XT!Y10), DAY(XT!AC10), DAY(XT!AG10)), MATCH(1, INDEX(--(MONTH(CHOOSE({1,2,3,4}, XT!U10,XT!Y10,XT!AC10,XT!AG10))=2), 0), 0)), "") | G10: =IF(XT!$P10>0,F10,"") | H10: =IF(XT!$P10=0,F10,"") | I10: =SUMPRODUCT((MONTH(CHOOSE({1,2,3,4},XT!U10,XT!Y10,XT!AC10,XT!AG10))=3)*(CHOOSE({1,2,3,4},XT!X10,XT!AB10,XT!AF10,XT!AJ10))) -> 0 | J10: =IFERROR(INDEX(CHOOSE({1,2,3,4}, DAY(XT!U10), DAY(XT!Y10), DAY(XT!AC10), DAY(XT!AG10)), MATCH(1, INDEX(--(MONTH(CHOOSE({1,2,3,4}, XT!U10,XT!Y10,XT!AC10,XT!AG10))=3), 0), 0)), "") | K10: =IF(XT!$P10>0,J10,"") | L10: =IF(XT!$P10=0,J10,"") | M10: =SUMPRODUCT((MONTH(CHOOSE({1,2,3,4},XT!U10,XT!Y10,XT!AC10,XT!AG10))=4)*(CHOOSE({1,2,3,4},XT!X10,XT!AB10,XT!AF10,XT!AJ10))) -> 0 | N10: =IFERROR(INDEX(CHOOSE({1,2,3,4}, DAY(XT!U10), DAY(XT!Y10), DAY(XT!AC10), DAY(XT!AG10)), MATCH(1, INDEX(--(MONTH(CHOOSE({1,2,3,4}, XT!U10,XT!Y10,XT!AC10,XT!AG10))=4), 0), 0)), "") | O10: =IF(XT!$P10>0,N10,"") | P10: =IF(XT!$P10=0,N10,"") | Q10: =SUMPRODUCT((MONTH(CHOOSE({1,2,3,4},XT!U10,XT!Y10,XT!AC10,XT!AG10))=5)*(CHOOSE({1,2,3,4},XT!X10,XT!AB10,XT!AF10,XT!AJ10))) -> 0 | R10: =IFERROR(INDEX(CHOOSE({1,2,3,4}, DAY(XT!U10), DAY(XT!Y10), DAY(XT!AC10), DAY(XT!AG10)), MATCH(1, INDEX(--(MONTH(CHOOSE({1,2,3,4}, XT!U10,XT!Y10,XT!AC10,XT!AG10))=5), 0), 0)), "") | S10: =IF(XT!$P10>0,R10,"") | T10: =IF(XT!$P10=0,R10,"") | U10: =SUMPRODUCT((MONTH(CHOOSE({1,2,3,4},XT!U10,XT!Y10,XT!AC10,XT!AG10))=6)*(CHOOSE({1,2,3,4},XT!X10,XT!AB10,XT!AF10,XT!AJ10))) -> 0 | V10: =IFERROR(INDEX(CHOOSE({1,2,3,4}, DAY(XT!U10), DAY(XT!Y10), DAY(XT!AC10), DAY(XT!AG10)), MATCH(1, INDEX(--(MONTH(CHOOSE({1,2,3,4}, XT!U10,XT!Y10,XT!AC10,XT!AG10))=6), 0), 0)), "") | W10: =IF(XT!$P10>0,V10,"") | X10: =IF(XT!$P10=0,V10,"") | Y10: =SUMPRODUCT((MONTH(CHOOSE({1,2,3,4},XT!U10,XT!Y10,XT!AC10,XT!AG10))=7)*(CHOOSE({1,2,3,4},XT!X10,XT!AB10,XT!AF10,XT!AJ10))) -> 0 | Z10: =IFERROR(INDEX(CHOOSE({1,2,3,4}, DAY(XT!U10), DAY(XT!Y10), DAY(XT!AC10), DAY(XT!AG10)), MATCH(1, INDEX(--(MONTH(CHOOSE({1,2,3,4}, XT!U10,XT!Y10,XT!AC10,XT!AG10))=7), 0), 0)), "") | AA10: =IF(XT!$P10>0,Z10,"") | AB10: =IF(XT!$P10=0,Z10,"") | AC10: =SUMPRODUCT((MONTH(CHOOSE({1,2,3,4},XT!U10,XT!Y10,XT!AC10,XT!AG10))=8)*(CHOOSE({1,2,3,4},XT!X10,XT!AB10,XT!AF10,XT!AJ10))) -> 0 | AD10: =IFERROR(INDEX(CHOOSE({1,2,3,4}, DAY(XT!U10), DAY(XT!Y10), DAY(XT!AC10), DAY(XT!AG10)), MATCH(1, INDEX(--(MONTH(CHOOSE({1,2,3,4}, XT!U10,XT!Y10,XT!AC10,XT!AG10))=8), 0), 0)), "") | AE10: =IF(XT!$P10>0,AD10,"") | AF10: =IF(XT!$P10=0,AD10,"") | AG10: =SUMPRODUCT((MONTH(CHOOSE({1,2,3,4},XT!U10,XT!Y10,XT!AC10,XT!AG10))=9)*(CHOOSE({1,2,3,4},XT!X10,XT!AB10,XT!AF10,XT!AJ10))) -> 0 | AH10: =IFERROR(INDEX(CHOOSE({1,2,3,4}, DAY(XT!U10), DAY(XT!Y10), DAY(XT!AC10), DAY(XT!AG10)), MATCH(1, INDEX(--(MONTH(CHOOSE({1,2,3,4}, XT!U10,XT!Y10,XT!AC10,XT!AG10))=9), 0), 0)), "") | AI10: =IF(XT!$P10>0,AH10,"") | AJ10: =IF(XT!$P10=0,AH10,"") | AK10: =SUMPRODUCT((MONTH(CHOOSE({1,2,3,4},XT!U10,XT!Y10,XT!AC10,XT!AG10))=10)*(CHOOSE({1,2,3,4},XT!X10,XT!AB10,XT!AF10,XT!AJ10))) -> 0 | AL10: =IFERROR(INDEX(CHOOSE({1,2,3,4}, DAY(XT!U10), DAY(XT!Y10), DAY(XT!AC10), DAY(XT!AG10)), MATCH(1, INDEX(--(MONTH(CHOOSE({1,2,3,4}, XT!U10,XT!Y10,XT!AC10,XT!AG10))=10), 0), 0)), "") | AM10: =IF(XT!$P10>0,AL10,"") | AN10: =IF(XT!$P10=0,AL10,"") | AO10: =SUMPRODUCT((MONTH(CHOOSE({1,2,3,4},XT!U10,XT!Y10,XT!AC10,XT!AG10))=11)*(CHOOSE({1,2,3,4},XT!X10,XT!AB10,XT!AF10,XT!AJ10))) -> 0 | AP10: =IFERROR(INDEX(CHOOSE({1,2,3,4}, DAY(XT!U10), DAY(XT!Y10), DAY(XT!AC10), DAY(XT!AG10)), MATCH(1, INDEX(--(MONTH(CHOOSE({1,2,3,4}, XT!U10,XT!Y10,XT!AC10,XT!AG10))=11), 0), 0)), "") | AQ10: =IF(XT!$P10>0,AP10,"") | AR10: =IF(XT!$P10=0,AP10,"") | AS10: =SUMPRODUCT((MONTH(CHOOSE({1,2,3,4},XT!U10,XT!Y10,XT!AC10,XT!AG10))=12)*(CHOOSE({1,2,3,4},XT!X10,XT!AB10,XT!AF10,XT!AJ10))) -> 0 | AT10: =IFERROR(INDEX(CHOOSE({1,2,3,4}, DAY(XT!U10), DAY(XT!Y10), DAY(XT!AC10), DAY(XT!AG10)), MATCH(1, INDEX(--(MONTH(CHOOSE({1,2,3,4}, XT!U10,XT!Y10,XT!AC10,XT!AG10))=12), 0), 0)), "") | AU10: =IF(XT!$P10>0,AT10,"") | AV10: =IF(XT!$P10=0,AT10,"")
A11: =SUMPRODUCT((MONTH(CHOOSE({1,2,3,4},XT!U11,XT!Y11,XT!AC11,XT!AG11))=1)*(CHOOSE({1,2,3,4},XT!X11,XT!AB11,XT!AF11,XT!AJ11))) -> 0 | B11: =IFERROR(INDEX(CHOOSE({1,2,3,4}, DAY(XT!U11), DAY(XT!Y11), DAY(XT!AC11), DAY(XT!AG11)), MATCH(1, INDEX(--(MONTH(CHOOSE({1,2,3,4}, XT!U11,XT!Y11,XT!AC11,XT!AG11))=1), 0), 0)), "") -> 0 | C11: =IF(XT!$P11>0,B11,"") | D11: =IF(XT!$P11=0,B11,"") -> 0 | E11: =SUMPRODUCT((MONTH(CHOOSE({1,2,3,4},XT!U11,XT!Y11,XT!AC11,XT!AG11))=2)*(CHOOSE({1,2,3,4},XT!X11,XT!AB11,XT!AF11,XT!AJ11))) -> 0 | F11: =IFERROR(INDEX(CHOOSE({1,2,3,4}, DAY(XT!U11), DAY(XT!Y11), DAY(XT!AC11), DAY(XT!AG11)), MATCH(1, INDEX(--(MONTH(CHOOSE({1,2,3,4}, XT!U11,XT!Y11,XT!AC11,XT!AG11))=2), 0), 0)), "") | G11: =IF(XT!$P11>0,F11,"") | H11: =IF(XT!$P11=0,F11,"") | I11: =SUMPRODUCT((MONTH(CHOOSE({1,2,3,4},XT!U11,XT!Y11,XT!AC11,XT!AG11))=3)*(CHOOSE({1,2,3,4},XT!X11,XT!AB11,XT!AF11,XT!AJ11))) -> 0 | J11: =IFERROR(INDEX(CHOOSE({1,2,3,4}, DAY(XT!U11), DAY(XT!Y11), DAY(XT!AC11), DAY(XT!AG11)), MATCH(1, INDEX(--(MONTH(CHOOSE({1,2,3,4}, XT!U11,XT!Y11,XT!AC11,XT!AG11))=3), 0), 0)), "") | K11: =IF(XT!$P11>0,J11,"") | L11: =IF(XT!$P11=0,J11,"") | M11: =SUMPRODUCT((MONTH(CHOOSE({1,2,3,4},XT!U11,XT!Y11,XT!AC11,XT!AG11))=4)*(CHOOSE({1,2,3,4},XT!X11,XT!AB11,XT!AF11,XT!AJ11))) -> 0 | N11: =IFERROR(INDEX(CHOOSE({1,2,3,4}, DAY(XT!U11), DAY(XT!Y11), DAY(XT!AC11), DAY(XT!AG11)), MATCH(1, INDEX(--(MONTH(CHOOSE({1,2,3,4}, XT!U11,XT!Y11,XT!AC11,XT!AG11))=4), 0), 0)), "") | O11: =IF(XT!$P11>0,N11,"") | P11: =IF(XT!$P11=0,N11,"") | Q11: =SUMPRODUCT((MONTH(CHOOSE({1,2,3,4},XT!U11,XT!Y11,XT!AC11,XT!AG11))=5)*(CHOOSE({1,2,3,4},XT!X11,XT!AB11,XT!AF11,XT!AJ11))) -> 0 | R11: =IFERROR(INDEX(CHOOSE({1,2,3,4}, DAY(XT!U11), DAY(XT!Y11), DAY(XT!AC11), DAY(XT!AG11)), MATCH(1, INDEX(--(MONTH(CHOOSE({1,2,3,4}, XT!U11,XT!Y11,XT!AC11,XT!AG11))=5), 0), 0)), "") | S11: =IF(XT!$P11>0,R11,"") | T11: =IF(XT!$P11=0,R11,"") | U11: =SUMPRODUCT((MONTH(CHOOSE({1,2,3,4},XT!U11,XT!Y11,XT!AC11,XT!AG11))=6)*(CHOOSE({1,2,3,4},XT!X11,XT!AB11,XT!AF11,XT!AJ11))) -> 0 | V11: =IFERROR(INDEX(CHOOSE({1,2,3,4}, DAY(XT!U11), DAY(XT!Y11), DAY(XT!AC11), DAY(XT!AG11)), MATCH(1, INDEX(--(MONTH(CHOOSE({1,2,3,4}, XT!U11,XT!Y11,XT!AC11,XT!AG11))=6), 0), 0)), "") | W11: =IF(XT!$P11>0,V11,"") | X11: =IF(XT!$P11=0,V11,"") | Y11: =SUMPRODUCT((MONTH(CHOOSE({1,2,3,4},XT!U11,XT!Y11,XT!AC11,XT!AG11))=7)*(CHOOSE({1,2,3,4},XT!X11,XT!AB11,XT!AF11,XT!AJ11))) -> 0 | Z11: =IFERROR(INDEX(CHOOSE({1,2,3,4}, DAY(XT!U11), DAY(XT!Y11), DAY(XT!AC11), DAY(XT!AG11)), MATCH(1, INDEX(--(MONTH(CHOOSE({1,2,3,4}, XT!U11,XT!Y11,XT!AC11,XT!AG11))=7), 0), 0)), "") | AA11: =IF(XT!$P11>0,Z11,"") | AB11: =IF(XT!$P11=0,Z11,"") | AC11: =SUMPRODUCT((MONTH(CHOOSE({1,2,3,4},XT!U11,XT!Y11,XT!AC11,XT!AG11))=8)*(CHOOSE({1,2,3,4},XT!X11,XT!AB11,XT!AF11,XT!AJ11))) -> 0 | AD11: =IFERROR(INDEX(CHOOSE({1,2,3,4}, DAY(XT!U11), DAY(XT!Y11), DAY(XT!AC11), DAY(XT!AG11)), MATCH(1, INDEX(--(MONTH(CHOOSE({1,2,3,4}, XT!U11,XT!Y11,XT!AC11,XT!AG11))=8), 0), 0)), "") | AE11: =IF(XT!$P11>0,AD11,"") | AF11: =IF(XT!$P11=0,AD11,"") | AG11: =SUMPRODUCT((MONTH(CHOOSE({1,2,3,4},XT!U11,XT!Y11,XT!AC11,XT!AG11))=9)*(CHOOSE({1,2,3,4},XT!X11,XT!AB11,XT!AF11,XT!AJ11))) -> 0 | AH11: =IFERROR(INDEX(CHOOSE({1,2,3,4}, DAY(XT!U11), DAY(XT!Y11), DAY(XT!AC11), DAY(XT!AG11)), MATCH(1, INDEX(--(MONTH(CHOOSE({1,2,3,4}, XT!U11,XT!Y11,XT!AC11,XT!AG11))=9), 0), 0)), "") | AI11: =IF(XT!$P11>0,AH11,"") | AJ11: =IF(XT!$P11=0,AH11,"") | AK11: =SUMPRODUCT((MONTH(CHOOSE({1,2,3,4},XT!U11,XT!Y11,XT!AC11,XT!AG11))=10)*(CHOOSE({1,2,3,4},XT!X11,XT!AB11,XT!AF11,XT!AJ11))) -> 0 | AL11: =IFERROR(INDEX(CHOOSE({1,2,3,4}, DAY(XT!U11), DAY(XT!Y11), DAY(XT!AC11), DAY(XT!AG11)), MATCH(1, INDEX(--(MONTH(CHOOSE({1,2,3,4}, XT!U11,XT!Y11,XT!AC11,XT!AG11))=10), 0), 0)), "") | AM11: =IF(XT!$P11>0,AL11,"") | AN11: =IF(XT!$P11=0,AL11,"") | AO11: =SUMPRODUCT((MONTH(CHOOSE({1,2,3,4},XT!U11,XT!Y11,XT!AC11,XT!AG11))=11)*(CHOOSE({1,2,3,4},XT!X11,XT!AB11,XT!AF11,XT!AJ11))) -> 0 | AP11: =IFERROR(INDEX(CHOOSE({1,2,3,4}, DAY(XT!U11), DAY(XT!Y11), DAY(XT!AC11), DAY(XT!AG11)), MATCH(1, INDEX(--(MONTH(CHOOSE({1,2,3,4}, XT!U11,XT!Y11,XT!AC11,XT!AG11))=11), 0), 0)), "") | AQ11: =IF(XT!$P11>0,AP11,"") | AR11: =IF(XT!$P11=0,AP11,"") | AS11: =SUMPRODUCT((MONTH(CHOOSE({1,2,3,4},XT!U11,XT!Y11,XT!AC11,XT!AG11))=12)*(CHOOSE({1,2,3,4},XT!X11,XT!AB11,XT!AF11,XT!AJ11))) -> 0 | AT11: =IFERROR(INDEX(CHOOSE({1,2,3,4}, DAY(XT!U11), DAY(XT!Y11), DAY(XT!AC11), DAY(XT!AG11)), MATCH(1, INDEX(--(MONTH(CHOOSE({1,2,3,4}, XT!U11,XT!Y11,XT!AC11,XT!AG11))=12), 0), 0)), "") | AU11: =IF(XT!$P11>0,AT11,"") | AV11: =IF(XT!$P11=0,AT11,"")
A12: =SUMPRODUCT((MONTH(CHOOSE({1,2,3,4},XT!U12,XT!Y12,XT!AC12,XT!AG12))=1)*(CHOOSE({1,2,3,4},XT!X12,XT!AB12,XT!AF12,XT!AJ12))) -> 0 | B12: =IFERROR(INDEX(CHOOSE({1,2,3,4}, DAY(XT!U12), DAY(XT!Y12), DAY(XT!AC12), DAY(XT!AG12)), MATCH(1, INDEX(--(MONTH(CHOOSE({1,2,3,4}, XT!U12,XT!Y12,XT!AC12,XT!AG12))=1), 0), 0)), "") -> 0 | C12: =IF(XT!$P12>0,B12,"") | D12: =IF(XT!$P12=0,B12,"") -> 0 | E12: =SUMPRODUCT((MONTH(CHOOSE({1,2,3,4},XT!U12,XT!Y12,XT!AC12,XT!AG12))=2)*(CHOOSE({1,2,3,4},XT!X12,XT!AB12,XT!AF12,XT!AJ12))) -> 0 | F12: =IFERROR(INDEX(CHOOSE({1,2,3,4}, DAY(XT!U12), DAY(XT!Y12), DAY(XT!AC12), DAY(XT!AG12)), MATCH(1, INDEX(--(MONTH(CHOOSE({1,2,3,4}, XT!U12,XT!Y12,XT!AC12,XT!AG12))=2), 0), 0)), "") | G12: =IF(XT!$P12>0,F12,"") | H12: =IF(XT!$P12=0,F12,"") | I12: =SUMPRODUCT((MONTH(CHOOSE({1,2,3,4},XT!U12,XT!Y12,XT!AC12,XT!AG12))=3)*(CHOOSE({1,2,3,4},XT!X12,XT!AB12,XT!AF12,XT!AJ12))) -> 0 | J12: =IFERROR(INDEX(CHOOSE({1,2,3,4}, DAY(XT!U12), DAY(XT!Y12), DAY(XT!AC12), DAY(XT!AG12)), MATCH(1, INDEX(--(MONTH(CHOOSE({1,2,3,4}, XT!U12,XT!Y12,XT!AC12,XT!AG12))=3), 0), 0)), "") | K12: =IF(XT!$P12>0,J12,"") | L12: =IF(XT!$P12=0,J12,"") | M12: =SUMPRODUCT((MONTH(CHOOSE({1,2,3,4},XT!U12,XT!Y12,XT!AC12,XT!AG12))=4)*(CHOOSE({1,2,3,4},XT!X12,XT!AB12,XT!AF12,XT!AJ12))) -> 0 | N12: =IFERROR(INDEX(CHOOSE({1,2,3,4}, DAY(XT!U12), DAY(XT!Y12), DAY(XT!AC12), DAY(XT!AG12)), MATCH(1, INDEX(--(MONTH(CHOOSE({1,2,3,4}, XT!U12,XT!Y12,XT!AC12,XT!AG12))=4), 0), 0)), "") | O12: =IF(XT!$P12>0,N12,"") | P12: =IF(XT!$P12=0,N12,"") | Q12: =SUMPRODUCT((MONTH(CHOOSE({1,2,3,4},XT!U12,XT!Y12,XT!AC12,XT!AG12))=5)*(CHOOSE({1,2,3,4},XT!X12,XT!AB12,XT!AF12,XT!AJ12))) -> 0 | R12: =IFERROR(INDEX(CHOOSE({1,2,3,4}, DAY(XT!U12), DAY(XT!Y12), DAY(XT!AC12), DAY(XT!AG12)), MATCH(1, INDEX(--(MONTH(CHOOSE({1,2,3,4}, XT!U12,XT!Y12,XT!AC12,XT!AG12))=5), 0), 0)), "") | S12: =IF(XT!$P12>0,R12,"") | T12: =IF(XT!$P12=0,R12,"") | U12: =SUMPRODUCT((MONTH(CHOOSE({1,2,3,4},XT!U12,XT!Y12,XT!AC12,XT!AG12))=6)*(CHOOSE({1,2,3,4},XT!X12,XT!AB12,XT!AF12,XT!AJ12))) -> 0 | V12: =IFERROR(INDEX(CHOOSE({1,2,3,4}, DAY(XT!U12), DAY(XT!Y12), DAY(XT!AC12), DAY(XT!AG12)), MATCH(1, INDEX(--(MONTH(CHOOSE({1,2,3,4}, XT!U12,XT!Y12,XT!AC12,XT!AG12))=6), 0), 0)), "") | W12: =IF(XT!$P12>0,V12,"") | X12: =IF(XT!$P12=0,V12,"") | Y12: =SUMPRODUCT((MONTH(CHOOSE({1,2,3,4},XT!U12,XT!Y12,XT!AC12,XT!AG12))=7)*(CHOOSE({1,2,3,4},XT!X12,XT!AB12,XT!AF12,XT!AJ12))) -> 0 | Z12: =IFERROR(INDEX(CHOOSE({1,2,3,4}, DAY(XT!U12), DAY(XT!Y12), DAY(XT!AC12), DAY(XT!AG12)), MATCH(1, INDEX(--(MONTH(CHOOSE({1,2,3,4}, XT!U12,XT!Y12,XT!AC12,XT!AG12))=7), 0), 0)), "") | AA12: =IF(XT!$P12>0,Z12,"") | AB12: =IF(XT!$P12=0,Z12,"") | AC12: =SUMPRODUCT((MONTH(CHOOSE({1,2,3,4},XT!U12,XT!Y12,XT!AC12,XT!AG12))=8)*(CHOOSE({1,2,3,4},XT!X12,XT!AB12,XT!AF12,XT!AJ12))) -> 0 | AD12: =IFERROR(INDEX(CHOOSE({1,2,3,4}, DAY(XT!U12), DAY(XT!Y12), DAY(XT!AC12), DAY(XT!AG12)), MATCH(1, INDEX(--(MONTH(CHOOSE({1,2,3,4}, XT!U12,XT!Y12,XT!AC12,XT!AG12))=8), 0), 0)), "") | AE12: =IF(XT!$P12>0,AD12,"") | AF12: =IF(XT!$P12=0,AD12,"") | AG12: =SUMPRODUCT((MONTH(CHOOSE({1,2,3,4},XT!U12,XT!Y12,XT!AC12,XT!AG12))=9)*(CHOOSE({1,2,3,4},XT!X12,XT!AB12,XT!AF12,XT!AJ12))) -> 0 | AH12: =IFERROR(INDEX(CHOOSE({1,2,3,4}, DAY(XT!U12), DAY(XT!Y12), DAY(XT!AC12), DAY(XT!AG12)), MATCH(1, INDEX(--(MONTH(CHOOSE({1,2,3,4}, XT!U12,XT!Y12,XT!AC12,XT!AG12))=9), 0), 0)), "") | AI12: =IF(XT!$P12>0,AH12,"") | AJ12: =IF(XT!$P12=0,AH12,"") | AK12: =SUMPRODUCT((MONTH(CHOOSE({1,2,3,4},XT!U12,XT!Y12,XT!AC12,XT!AG12))=10)*(CHOOSE({1,2,3,4},XT!X12,XT!AB12,XT!AF12,XT!AJ12))) -> 0 | AL12: =IFERROR(INDEX(CHOOSE({1,2,3,4}, DAY(XT!U12), DAY(XT!Y12), DAY(XT!AC12), DAY(XT!AG12)), MATCH(1, INDEX(--(MONTH(CHOOSE({1,2,3,4}, XT!U12,XT!Y12,XT!AC12,XT!AG12))=10), 0), 0)), "") | AM12: =IF(XT!$P12>0,AL12,"") | AN12: =IF(XT!$P12=0,AL12,"") | AO12: =SUMPRODUCT((MONTH(CHOOSE({1,2,3,4},XT!U12,XT!Y12,XT!AC12,XT!AG12))=11)*(CHOOSE({1,2,3,4},XT!X12,XT!AB12,XT!AF12,XT!AJ12))) -> 0 | AP12: =IFERROR(INDEX(CHOOSE({1,2,3,4}, DAY(XT!U12), DAY(XT!Y12), DAY(XT!AC12), DAY(XT!AG12)), MATCH(1, INDEX(--(MONTH(CHOOSE({1,2,3,4}, XT!U12,XT!Y12,XT!AC12,XT!AG12))=11), 0), 0)), "") | AQ12: =IF(XT!$P12>0,AP12,"") | AR12: =IF(XT!$P12=0,AP12,"") | AS12: =SUMPRODUCT((MONTH(CHOOSE({1,2,3,4},XT!U12,XT!Y12,XT!AC12,XT!AG12))=12)*(CHOOSE({1,2,3,4},XT!X12,XT!AB12,XT!AF12,XT!AJ12))) -> 0 | AT12: =IFERROR(INDEX(CHOOSE({1,2,3,4}, DAY(XT!U12), DAY(XT!Y12), DAY(XT!AC12), DAY(XT!AG12)), MATCH(1, INDEX(--(MONTH(CHOOSE({1,2,3,4}, XT!U12,XT!Y12,XT!AC12,XT!AG12))=12), 0), 0)), "") | AU12: =IF(XT!$P12>0,AT12,"") | AV12: =IF(XT!$P12=0,AT12,"")
A13: =SUMPRODUCT((MONTH(CHOOSE({1,2,3,4},XT!U13,XT!Y13,XT!AC13,XT!AG13))=1)*(CHOOSE({1,2,3,4},XT!X13,XT!AB13,XT!AF13,XT!AJ13))) -> 0 | B13: =IFERROR(INDEX(CHOOSE({1,2,3,4}, DAY(XT!U13), DAY(XT!Y13), DAY(XT!AC13), DAY(XT!AG13)), MATCH(1, INDEX(--(MONTH(CHOOSE({1,2,3,4}, XT!U13,XT!Y13,XT!AC13,XT!AG13))=1), 0), 0)), "") -> 0 | C13: =IF(XT!$P13>0,B13,"") | D13: =IF(XT!$P13=0,B13,"") -> 0 | E13: =SUMPRODUCT((MONTH(CHOOSE({1,2,3,4},XT!U13,XT!Y13,XT!AC13,XT!AG13))=2)*(CHOOSE({1,2,3,4},XT!X13,XT!AB13,XT!AF13,XT!AJ13))) -> 0 | F13: =IFERROR(INDEX(CHOOSE({1,2,3,4}, DAY(XT!U13), DAY(XT!Y13), DAY(XT!AC13), DAY(XT!AG13)), MATCH(1, INDEX(--(MONTH(CHOOSE({1,2,3,4}, XT!U13,XT!Y13,XT!AC13,XT!AG13))=2), 0), 0)), "") | G13: =IF(XT!$P13>0,F13,"") | H13: =IF(XT!$P13=0,F13,"") | I13: =SUMPRODUCT((MONTH(CHOOSE({1,2,3,4},XT!U13,XT!Y13,XT!AC13,XT!AG13))=3)*(CHOOSE({1,2,3,4},XT!X13,XT!AB13,XT!AF13,XT!AJ13))) -> 0 | J13: =IFERROR(INDEX(CHOOSE({1,2,3,4}, DAY(XT!U13), DAY(XT!Y13), DAY(XT!AC13), DAY(XT!AG13)), MATCH(1, INDEX(--(MONTH(CHOOSE({1,2,3,4}, XT!U13,XT!Y13,XT!AC13,XT!AG13))=3), 0), 0)), "") | K13: =IF(XT!$P13>0,J13,"") | L13: =IF(XT!$P13=0,J13,"") | M13: =SUMPRODUCT((MONTH(CHOOSE({1,2,3,4},XT!U13,XT!Y13,XT!AC13,XT!AG13))=4)*(CHOOSE({1,2,3,4},XT!X13,XT!AB13,XT!AF13,XT!AJ13))) -> 0 | N13: =IFERROR(INDEX(CHOOSE({1,2,3,4}, DAY(XT!U13), DAY(XT!Y13), DAY(XT!AC13), DAY(XT!AG13)), MATCH(1, INDEX(--(MONTH(CHOOSE({1,2,3,4}, XT!U13,XT!Y13,XT!AC13,XT!AG13))=4), 0), 0)), "") | O13: =IF(XT!$P13>0,N13,"") | P13: =IF(XT!$P13=0,N13,"") | Q13: =SUMPRODUCT((MONTH(CHOOSE({1,2,3,4},XT!U13,XT!Y13,XT!AC13,XT!AG13))=5)*(CHOOSE({1,2,3,4},XT!X13,XT!AB13,XT!AF13,XT!AJ13))) -> 0 | R13: =IFERROR(INDEX(CHOOSE({1,2,3,4}, DAY(XT!U13), DAY(XT!Y13), DAY(XT!AC13), DAY(XT!AG13)), MATCH(1, INDEX(--(MONTH(CHOOSE({1,2,3,4}, XT!U13,XT!Y13,XT!AC13,XT!AG13))=5), 0), 0)), "") | S13: =IF(XT!$P13>0,R13,"") | T13: =IF(XT!$P13=0,R13,"") | U13: =SUMPRODUCT((MONTH(CHOOSE({1,2,3,4},XT!U13,XT!Y13,XT!AC13,XT!AG13))=6)*(CHOOSE({1,2,3,4},XT!X13,XT!AB13,XT!AF13,XT!AJ13))) -> 0 | V13: =IFERROR(INDEX(CHOOSE({1,2,3,4}, DAY(XT!U13), DAY(XT!Y13), DAY(XT!AC13), DAY(XT!AG13)), MATCH(1, INDEX(--(MONTH(CHOOSE({1,2,3,4}, XT!U13,XT!Y13,XT!AC13,XT!AG13))=6), 0), 0)), "") | W13: =IF(XT!$P13>0,V13,"") | X13: =IF(XT!$P13=0,V13,"") | Y13: =SUMPRODUCT((MONTH(CHOOSE({1,2,3,4},XT!U13,XT!Y13,XT!AC13,XT!AG13))=7)*(CHOOSE({1,2,3,4},XT!X13,XT!AB13,XT!AF13,XT!AJ13))) -> 0 | Z13: =IFERROR(INDEX(CHOOSE({1,2,3,4}, DAY(XT!U13), DAY(XT!Y13), DAY(XT!AC13), DAY(XT!AG13)), MATCH(1, INDEX(--(MONTH(CHOOSE({1,2,3,4}, XT!U13,XT!Y13,XT!AC13,XT!AG13))=7), 0), 0)), "") | AA13: =IF(XT!$P13>0,Z13,"") | AB13: =IF(XT!$P13=0,Z13,"") | AC13: =SUMPRODUCT((MONTH(CHOOSE({1,2,3,4},XT!U13,XT!Y13,XT!AC13,XT!AG13))=8)*(CHOOSE({1,2,3,4},XT!X13,XT!AB13,XT!AF13,XT!AJ13))) -> 0 | AD13: =IFERROR(INDEX(CHOOSE({1,2,3,4}, DAY(XT!U13), DAY(XT!Y13), DAY(XT!AC13), DAY(XT!AG13)), MATCH(1, INDEX(--(MONTH(CHOOSE({1,2,3,4}, XT!U13,XT!Y13,XT!AC13,XT!AG13))=8), 0), 0)), "") | AE13: =IF(XT!$P13>0,AD13,"") | AF13: =IF(XT!$P13=0,AD13,"") | AG13: =SUMPRODUCT((MONTH(CHOOSE({1,2,3,4},XT!U13,XT!Y13,XT!AC13,XT!AG13))=9)*(CHOOSE({1,2,3,4},XT!X13,XT!AB13,XT!AF13,XT!AJ13))) -> 0 | AH13: =IFERROR(INDEX(CHOOSE({1,2,3,4}, DAY(XT!U13), DAY(XT!Y13), DAY(XT!AC13), DAY(XT!AG13)), MATCH(1, INDEX(--(MONTH(CHOOSE({1,2,3,4}, XT!U13,XT!Y13,XT!AC13,XT!AG13))=9), 0), 0)), "") | AI13: =IF(XT!$P13>0,AH13,"") | AJ13: =IF(XT!$P13=0,AH13,"") | AK13: =SUMPRODUCT((MONTH(CHOOSE({1,2,3,4},XT!U13,XT!Y13,XT!AC13,XT!AG13))=10)*(CHOOSE({1,2,3,4},XT!X13,XT!AB13,XT!AF13,XT!AJ13))) -> 0 | AL13: =IFERROR(INDEX(CHOOSE({1,2,3,4}, DAY(XT!U13), DAY(XT!Y13), DAY(XT!AC13), DAY(XT!AG13)), MATCH(1, INDEX(--(MONTH(CHOOSE({1,2,3,4}, XT!U13,XT!Y13,XT!AC13,XT!AG13))=10), 0), 0)), "") | AM13: =IF(XT!$P13>0,AL13,"") | AN13: =IF(XT!$P13=0,AL13,"") | AO13: =SUMPRODUCT((MONTH(CHOOSE({1,2,3,4},XT!U13,XT!Y13,XT!AC13,XT!AG13))=11)*(CHOOSE({1,2,3,4},XT!X13,XT!AB13,XT!AF13,XT!AJ13))) -> 0 | AP13: =IFERROR(INDEX(CHOOSE({1,2,3,4}, DAY(XT!U13), DAY(XT!Y13), DAY(XT!AC13), DAY(XT!AG13)), MATCH(1, INDEX(--(MONTH(CHOOSE({1,2,3,4}, XT!U13,XT!Y13,XT!AC13,XT!AG13))=11), 0), 0)), "") | AQ13: =IF(XT!$P13>0,AP13,"") | AR13: =IF(XT!$P13=0,AP13,"") | AS13: =SUMPRODUCT((MONTH(CHOOSE({1,2,3,4},XT!U13,XT!Y13,XT!AC13,XT!AG13))=12)*(CHOOSE({1,2,3,4},XT!X13,XT!AB13,XT!AF13,XT!AJ13))) -> 0 | AT13: =IFERROR(INDEX(CHOOSE({1,2,3,4}, DAY(XT!U13), DAY(XT!Y13), DAY(XT!AC13), DAY(XT!AG13)), MATCH(1, INDEX(--(MONTH(CHOOSE({1,2,3,4}, XT!U13,XT!Y13,XT!AC13,XT!AG13))=12), 0), 0)), "") | AU13: =IF(XT!$P13>0,AT13,"") | AV13: =IF(XT!$P13=0,AT13,"")
